---
title: Essayer... Catch... Finally, instruction
description: Apprenez à utiliser la gestion des exceptions avec Visual Basic instructions try/catch/finally.
ms.date: 12/07/2018
f1_keywords:
- vb.Try...Catch...Finally
- vb.when
- vb.Finally
- vb.Catch
- vb.Try
helpviewer_keywords:
- Try...Catch...Finally statements
- Try statement [Visual Basic]
- try-catch exception handling, Try...Catch...Finally statements
- error handling, while running code
- Try statement [Visual Basic], Try...Catch...Finally
- Finally keyword [Visual Basic], Try...Catch...Finally
- Catch statement [Visual Basic]
- When keyword [Visual Basic]
- Visual Basic code, handling errors while running
- structured exception handling, Try...Catch...Finally statements
ms.assetid: d6488026-ccb3-42b8-a810-0d97b9d6472b
ms.openlocfilehash: 22f1611786a3da512632b5b547b7ef141c8f65c6
ms.sourcegitcommit: f8c270376ed905f6a8896ce0fe25b4f4b38ff498
ms.translationtype: MT
ms.contentlocale: fr-FR
ms.lasthandoff: 06/04/2020
ms.locfileid: "84391766"
---
# <a name="trycatchfinally-statement-visual-basic"></a><span data-ttu-id="8355f-103">Try...Catch...Finally, instruction (Visual Basic)</span><span class="sxs-lookup"><span data-stu-id="8355f-103">Try...Catch...Finally Statement (Visual Basic)</span></span>

<span data-ttu-id="8355f-104">Fournit un moyen de gérer certaines ou toutes les erreurs possibles qui peuvent se produire dans un bloc de code donné, tout en continuant d’exécuter du code.</span><span class="sxs-lookup"><span data-stu-id="8355f-104">Provides a way to handle some or all possible errors that may occur in a given block of code, while still running code.</span></span>

## <a name="syntax"></a><span data-ttu-id="8355f-105">Syntaxe</span><span class="sxs-lookup"><span data-stu-id="8355f-105">Syntax</span></span>

```vb
Try
    [ tryStatements ]
    [ Exit Try ]
[ Catch [ exception [ As type ] ] [ When expression ]
    [ catchStatements ]
    [ Exit Try ] ]
[ Catch ... ]
[ Finally
    [ finallyStatements ] ]
End Try
```

## <a name="parts"></a><span data-ttu-id="8355f-106">Éléments</span><span class="sxs-lookup"><span data-stu-id="8355f-106">Parts</span></span>

|<span data-ttu-id="8355f-107">Terme</span><span class="sxs-lookup"><span data-stu-id="8355f-107">Term</span></span>|<span data-ttu-id="8355f-108">Définition</span><span class="sxs-lookup"><span data-stu-id="8355f-108">Definition</span></span>|
|---|---|
|`tryStatements`|<span data-ttu-id="8355f-109">Facultatif.</span><span class="sxs-lookup"><span data-stu-id="8355f-109">Optional.</span></span> <span data-ttu-id="8355f-110">Instruction (s) où une erreur peut se produire.</span><span class="sxs-lookup"><span data-stu-id="8355f-110">Statement(s) where an error can occur.</span></span> <span data-ttu-id="8355f-111">Il peut s'agir d'une instruction composée.</span><span class="sxs-lookup"><span data-stu-id="8355f-111">Can be a compound statement.</span></span>|
|`Catch`|<span data-ttu-id="8355f-112">Facultatif.</span><span class="sxs-lookup"><span data-stu-id="8355f-112">Optional.</span></span> <span data-ttu-id="8355f-113">`Catch`Blocs multiples autorisés.</span><span class="sxs-lookup"><span data-stu-id="8355f-113">Multiple `Catch` blocks permitted.</span></span> <span data-ttu-id="8355f-114">Si une exception se produit lors du traitement du `Try` bloc, chaque `Catch` instruction est examinée dans l’ordre textuel pour déterminer si elle gère l’exception, avec `exception` représentant l’exception qui a été levée.</span><span class="sxs-lookup"><span data-stu-id="8355f-114">If an exception occurs when processing the `Try` block, each `Catch` statement is examined in textual order to determine whether it handles the exception, with `exception` representing the exception that has been thrown.</span></span>|
|`exception`|<span data-ttu-id="8355f-115">Facultatif.</span><span class="sxs-lookup"><span data-stu-id="8355f-115">Optional.</span></span> <span data-ttu-id="8355f-116">Tout nom de variable.</span><span class="sxs-lookup"><span data-stu-id="8355f-116">Any variable name.</span></span> <span data-ttu-id="8355f-117">La valeur initiale de l'argument `exception` est la valeur de l'erreur levée.</span><span class="sxs-lookup"><span data-stu-id="8355f-117">The initial value of `exception` is the value of the thrown error.</span></span> <span data-ttu-id="8355f-118">Utilisé avec `Catch` pour spécifier l’erreur interceptée.</span><span class="sxs-lookup"><span data-stu-id="8355f-118">Used with `Catch` to specify the error caught.</span></span> <span data-ttu-id="8355f-119">En cas d’omission, l' `Catch` instruction intercepte toute exception.</span><span class="sxs-lookup"><span data-stu-id="8355f-119">If omitted, the `Catch` statement catches any exception.</span></span>|
|`type`|<span data-ttu-id="8355f-120">Facultatif.</span><span class="sxs-lookup"><span data-stu-id="8355f-120">Optional.</span></span> <span data-ttu-id="8355f-121">Spécifie le type de filtre de classe.</span><span class="sxs-lookup"><span data-stu-id="8355f-121">Specifies the type of class filter.</span></span> <span data-ttu-id="8355f-122">Si la valeur de `exception` est du type spécifié par `type` ou d’un type dérivé, l’identificateur est lié à l’objet d’exception.</span><span class="sxs-lookup"><span data-stu-id="8355f-122">If the value of `exception` is of the type specified by `type` or of a derived type, the identifier becomes bound to the exception object.</span></span>|
|`When`|<span data-ttu-id="8355f-123">Facultatif.</span><span class="sxs-lookup"><span data-stu-id="8355f-123">Optional.</span></span> <span data-ttu-id="8355f-124">Une `Catch` instruction avec une `When` clause intercepte les exceptions uniquement lorsque a la `expression` valeur `True` .</span><span class="sxs-lookup"><span data-stu-id="8355f-124">A `Catch` statement with a `When` clause catches exceptions only when `expression` evaluates to `True`.</span></span> <span data-ttu-id="8355f-125">Une `When` clause est appliquée uniquement après avoir vérifié le type de l’exception et `expression` peut faire référence à l’identificateur représentant l’exception.</span><span class="sxs-lookup"><span data-stu-id="8355f-125">A `When` clause is applied only after checking the type of the exception, and `expression` may refer to the identifier representing the exception.</span></span>|
|`expression`|<span data-ttu-id="8355f-126">Facultatif.</span><span class="sxs-lookup"><span data-stu-id="8355f-126">Optional.</span></span> <span data-ttu-id="8355f-127">Doit être implicitement convertible en `Boolean` .</span><span class="sxs-lookup"><span data-stu-id="8355f-127">Must be implicitly convertible to `Boolean`.</span></span> <span data-ttu-id="8355f-128">Toute expression qui décrit un filtre générique.</span><span class="sxs-lookup"><span data-stu-id="8355f-128">Any expression that describes a generic filter.</span></span> <span data-ttu-id="8355f-129">Généralement utilisé pour filtrer par numéro d’erreur.</span><span class="sxs-lookup"><span data-stu-id="8355f-129">Typically used to filter by error number.</span></span> <span data-ttu-id="8355f-130">Utilisé avec `When` le mot clé pour spécifier les circonstances dans lesquelles l’erreur est interceptée.</span><span class="sxs-lookup"><span data-stu-id="8355f-130">Used with `When` keyword to specify circumstances under which the error is caught.</span></span>|
|`catchStatements`|<span data-ttu-id="8355f-131">Facultatif.</span><span class="sxs-lookup"><span data-stu-id="8355f-131">Optional.</span></span> <span data-ttu-id="8355f-132">Instruction (s) pour gérer les erreurs qui se produisent dans le `Try` bloc associé.</span><span class="sxs-lookup"><span data-stu-id="8355f-132">Statement(s) to handle errors that occur in the associated `Try` block.</span></span> <span data-ttu-id="8355f-133">Il peut s'agir d'une instruction composée.</span><span class="sxs-lookup"><span data-stu-id="8355f-133">Can be a compound statement.</span></span>|
|`Exit Try`|<span data-ttu-id="8355f-134">Facultatif.</span><span class="sxs-lookup"><span data-stu-id="8355f-134">Optional.</span></span> <span data-ttu-id="8355f-135">Mot clé qui s’arrête hors de la `Try...Catch...Finally` structure.</span><span class="sxs-lookup"><span data-stu-id="8355f-135">Keyword that breaks out of the `Try...Catch...Finally` structure.</span></span> <span data-ttu-id="8355f-136">L’exécution reprend avec le code qui suit immédiatement l' `End Try` instruction.</span><span class="sxs-lookup"><span data-stu-id="8355f-136">Execution resumes with the code immediately following the `End Try` statement.</span></span> <span data-ttu-id="8355f-137">L' `Finally` instruction est toujours exécutée.</span><span class="sxs-lookup"><span data-stu-id="8355f-137">The `Finally` statement will still be executed.</span></span> <span data-ttu-id="8355f-138">Non autorisé dans les `Finally` blocs.</span><span class="sxs-lookup"><span data-stu-id="8355f-138">Not allowed in `Finally` blocks.</span></span>|
|`Finally`|<span data-ttu-id="8355f-139">Facultatif.</span><span class="sxs-lookup"><span data-stu-id="8355f-139">Optional.</span></span> <span data-ttu-id="8355f-140">Un `Finally` bloc est toujours exécuté lorsque l’exécution quitte une partie de l' `Try...Catch` instruction.</span><span class="sxs-lookup"><span data-stu-id="8355f-140">A `Finally` block is always executed when execution leaves any part of the `Try...Catch` statement.</span></span>|
|`finallyStatements`|<span data-ttu-id="8355f-141">Facultatif.</span><span class="sxs-lookup"><span data-stu-id="8355f-141">Optional.</span></span> <span data-ttu-id="8355f-142">Instruction (s) qui sont exécutées une fois que toutes les autres opérations de traitement des erreurs se sont produites.</span><span class="sxs-lookup"><span data-stu-id="8355f-142">Statement(s) that are executed after all other error processing has occurred.</span></span>|
|`End Try`|<span data-ttu-id="8355f-143">Met fin à la `Try...Catch...Finally` structure.</span><span class="sxs-lookup"><span data-stu-id="8355f-143">Terminates the `Try...Catch...Finally` structure.</span></span>|

## <a name="remarks"></a><span data-ttu-id="8355f-144">Notes</span><span class="sxs-lookup"><span data-stu-id="8355f-144">Remarks</span></span>

<span data-ttu-id="8355f-145">Si vous vous attendez à ce qu’une exception particulière se produise au cours d’une section de code particulière, placez le code dans un `Try` bloc et utilisez un `Catch` bloc pour conserver le contrôle et gérer l’exception, le cas échéant.</span><span class="sxs-lookup"><span data-stu-id="8355f-145">If you expect that a particular exception might occur during a particular section of code, put the code in a `Try` block and use a `Catch` block to retain control and handle the exception if it occurs.</span></span>

<span data-ttu-id="8355f-146">Une `Try…Catch` instruction se compose d’un `Try` bloc suivi d’une ou `Catch` de plusieurs clauses, qui spécifient des gestionnaires pour différentes exceptions.</span><span class="sxs-lookup"><span data-stu-id="8355f-146">A `Try…Catch` statement consists of a `Try` block followed by one or more `Catch` clauses, which specify handlers for various exceptions.</span></span> <span data-ttu-id="8355f-147">Quand une exception est levée dans un `Try` bloc, Visual Basic recherche l' `Catch` instruction qui gère l’exception.</span><span class="sxs-lookup"><span data-stu-id="8355f-147">When an exception is thrown in a `Try` block, Visual Basic looks for the `Catch` statement that handles the exception.</span></span> <span data-ttu-id="8355f-148">Si une `Catch` instruction correspondante est introuvable, Visual Basic examine la méthode qui a appelé la méthode actuelle, et ainsi de suite la pile des appels.</span><span class="sxs-lookup"><span data-stu-id="8355f-148">If a matching `Catch` statement is not found, Visual Basic examines the method that called the current method, and so on up the call stack.</span></span> <span data-ttu-id="8355f-149">Si aucun `Catch` bloc n’est trouvé, Visual Basic affiche un message d’exception non gérée à l’utilisateur et arrête l’exécution du programme.</span><span class="sxs-lookup"><span data-stu-id="8355f-149">If no `Catch` block is found, Visual Basic displays an unhandled exception message to the user and stops execution of the program.</span></span>

<span data-ttu-id="8355f-150">Vous pouvez utiliser plusieurs `Catch` instructions dans une `Try…Catch` instruction.</span><span class="sxs-lookup"><span data-stu-id="8355f-150">You can use more than one `Catch` statement in a `Try…Catch` statement.</span></span> <span data-ttu-id="8355f-151">Dans ce cas, l’ordre des `Catch` clauses est significatif, car ils sont examinés dans l’ordre.</span><span class="sxs-lookup"><span data-stu-id="8355f-151">If you do this, the order of the `Catch` clauses is significant because they are examined in order.</span></span> <span data-ttu-id="8355f-152">Interceptez les exceptions plus spécifiques avant les moins spécifiques.</span><span class="sxs-lookup"><span data-stu-id="8355f-152">Catch the more specific exceptions before the less specific ones.</span></span>

<span data-ttu-id="8355f-153">Les `Catch` conditions d’instruction suivantes sont les moins spécifiques et interceptent toutes les exceptions qui dérivent de la <xref:System.Exception> classe.</span><span class="sxs-lookup"><span data-stu-id="8355f-153">The following `Catch` statement conditions are the least specific, and will catch all exceptions that derive from the <xref:System.Exception> class.</span></span> <span data-ttu-id="8355f-154">En principe, vous devez utiliser l’une de ces variations comme dernier `Catch` bloc de la `Try...Catch...Finally` structure, après avoir intercepté toutes les exceptions spécifiques que vous attendez.</span><span class="sxs-lookup"><span data-stu-id="8355f-154">You should ordinarily use one of these variations as the last `Catch` block in the `Try...Catch...Finally` structure, after catching all the specific exceptions you expect.</span></span> <span data-ttu-id="8355f-155">Le workflow de contrôle ne peut jamais atteindre un `Catch` bloc qui suit l’une de ces variantes.</span><span class="sxs-lookup"><span data-stu-id="8355f-155">Control flow can never reach a `Catch` block that follows either of these variations.</span></span>

- <span data-ttu-id="8355f-156">`type`Est `Exception` , par exemple :`Catch ex As Exception`</span><span class="sxs-lookup"><span data-stu-id="8355f-156">The `type` is `Exception`, for example: `Catch ex As Exception`</span></span>

- <span data-ttu-id="8355f-157">L’instruction n’a pas `exception` de variable, par exemple :`Catch`</span><span class="sxs-lookup"><span data-stu-id="8355f-157">The statement has no `exception` variable, for example: `Catch`</span></span>

<span data-ttu-id="8355f-158">Lorsqu’une `Try…Catch…Finally` instruction est imbriquée dans un autre `Try` bloc, Visual Basic examine d’abord chaque `Catch` instruction dans le bloc le plus profond `Try` .</span><span class="sxs-lookup"><span data-stu-id="8355f-158">When a `Try…Catch…Finally` statement is nested in another `Try` block, Visual Basic first examines each `Catch` statement in the innermost `Try` block.</span></span> <span data-ttu-id="8355f-159">Si aucune `Catch` instruction correspondante n’est trouvée, la recherche se poursuit sur les `Catch` instructions du `Try…Catch…Finally` bloc externe.</span><span class="sxs-lookup"><span data-stu-id="8355f-159">If no matching `Catch` statement is found, the search proceeds to the `Catch` statements of the outer `Try…Catch…Finally` block.</span></span>

<span data-ttu-id="8355f-160">Les variables locales d’un `Try` bloc ne sont pas disponibles dans un `Catch` bloc, car il s’agit de blocs distincts.</span><span class="sxs-lookup"><span data-stu-id="8355f-160">Local variables from a `Try` block are not available in a `Catch` block because they are separate blocks.</span></span> <span data-ttu-id="8355f-161">Si vous souhaitez utiliser une variable dans plusieurs blocs, déclarez la variable en dehors de la `Try...Catch...Finally` structure.</span><span class="sxs-lookup"><span data-stu-id="8355f-161">If you want to use a variable in more than one block, declare the variable outside the `Try...Catch...Finally` structure.</span></span>

> [!TIP]
> <span data-ttu-id="8355f-162">L' `Try…Catch…Finally` instruction est disponible sous la forme d’un extrait de code IntelliSense.</span><span class="sxs-lookup"><span data-stu-id="8355f-162">The `Try…Catch…Finally` statement is available as an IntelliSense code snippet.</span></span> <span data-ttu-id="8355f-163">Dans le gestionnaire des extraits de code, développez **modèles de code-If, for each, try catch, Property, etc**, puis la **gestion des erreurs (exceptions)**.</span><span class="sxs-lookup"><span data-stu-id="8355f-163">In the Code Snippets Manager, expand **Code Patterns - If, For Each, Try Catch, Property, etc**, and then **Error Handling (Exceptions)**.</span></span> <span data-ttu-id="8355f-164">Pour plus d’informations, consultez [Extraits de code](/visualstudio/ide/code-snippets).</span><span class="sxs-lookup"><span data-stu-id="8355f-164">For more information, see [Code Snippets](/visualstudio/ide/code-snippets).</span></span>

## <a name="finally-block"></a><span data-ttu-id="8355f-165">Finally (bloc)</span><span class="sxs-lookup"><span data-stu-id="8355f-165">Finally block</span></span>

<span data-ttu-id="8355f-166">Si vous avez une ou plusieurs instructions qui doivent s’exécuter avant de quitter la `Try` structure, utilisez un `Finally` bloc.</span><span class="sxs-lookup"><span data-stu-id="8355f-166">If you have one or more statements that must run before you exit the `Try` structure, use a `Finally` block.</span></span> <span data-ttu-id="8355f-167">Le contrôle est passé au `Finally` bloc juste avant qu’il ne soit en dehors de la `Try…Catch` structure.</span><span class="sxs-lookup"><span data-stu-id="8355f-167">Control passes to the `Finally` block just before it passes out of the `Try…Catch` structure.</span></span> <span data-ttu-id="8355f-168">Cela est vrai même si une exception se produit n’importe où dans la `Try` structure.</span><span class="sxs-lookup"><span data-stu-id="8355f-168">This is true even if an exception occurs anywhere inside the `Try` structure.</span></span>

<span data-ttu-id="8355f-169">Un `Finally` bloc est utile pour exécuter tout code qui doit s’exécuter même en cas d’exception.</span><span class="sxs-lookup"><span data-stu-id="8355f-169">A `Finally` block is useful for running any code that must execute even if there is an exception.</span></span> <span data-ttu-id="8355f-170">Le contrôle est passé au `Finally` bloc, quelle que soit la façon dont le `Try...Catch` bloc s’arrête.</span><span class="sxs-lookup"><span data-stu-id="8355f-170">Control is passed to the `Finally` block regardless of how the `Try...Catch` block exits.</span></span>

<span data-ttu-id="8355f-171">Le code d’un `Finally` bloc s’exécute même si votre code rencontre une `Return` instruction dans un `Try` bloc ou `Catch` .</span><span class="sxs-lookup"><span data-stu-id="8355f-171">The code in a `Finally` block runs even if your code encounters a `Return` statement in a `Try` or `Catch` block.</span></span> <span data-ttu-id="8355f-172">Le contrôle ne passe pas d' `Try` un `Catch` bloc ou au `Finally` bloc correspondant dans les cas suivants :</span><span class="sxs-lookup"><span data-stu-id="8355f-172">Control does not pass from a `Try` or `Catch` block to the corresponding `Finally` block in the following cases:</span></span>

- <span data-ttu-id="8355f-173">Une [instruction end](end-statement.md) est rencontrée dans `Try` le `Catch` bloc ou.</span><span class="sxs-lookup"><span data-stu-id="8355f-173">An [End Statement](end-statement.md) is encountered in the `Try` or `Catch` block.</span></span>

- <span data-ttu-id="8355f-174">Une <xref:System.StackOverflowException> est levée dans le `Try` `Catch` bloc ou.</span><span class="sxs-lookup"><span data-stu-id="8355f-174">A <xref:System.StackOverflowException> is thrown in the `Try` or `Catch` block.</span></span>

<span data-ttu-id="8355f-175">Il n’est pas possible de transférer explicitement l’exécution dans un `Finally` bloc.</span><span class="sxs-lookup"><span data-stu-id="8355f-175">It is not valid to explicitly transfer execution into a `Finally` block.</span></span> <span data-ttu-id="8355f-176">Le transfert de l’exécution en dehors d’un `Finally` bloc n’est pas valide, sauf par le biais d’une exception.</span><span class="sxs-lookup"><span data-stu-id="8355f-176">Transferring execution out of a `Finally` block is not valid, except through an exception.</span></span>

<span data-ttu-id="8355f-177">Si une `Try` instruction ne contient pas au moins un `Catch` bloc, elle doit contenir un `Finally` bloc.</span><span class="sxs-lookup"><span data-stu-id="8355f-177">If a `Try` statement does not contain at least one `Catch` block, it must contain a `Finally` block.</span></span>

> [!TIP]
> <span data-ttu-id="8355f-178">Si vous n’avez pas besoin d’intercepter des exceptions spécifiques, l' `Using` instruction se comporte comme un `Try…Finally` bloc et garantit la suppression des ressources, quelle que soit la façon dont vous quittez le bloc.</span><span class="sxs-lookup"><span data-stu-id="8355f-178">If you do not have to catch specific exceptions, the `Using` statement behaves like a `Try…Finally` block, and guarantees disposal of the resources, regardless of how you exit the block.</span></span> <span data-ttu-id="8355f-179">Cela est vrai même avec une exception non gérée.</span><span class="sxs-lookup"><span data-stu-id="8355f-179">This is true even with an unhandled exception.</span></span> <span data-ttu-id="8355f-180">Pour plus d’informations, consultez [using, instruction](using-statement.md).</span><span class="sxs-lookup"><span data-stu-id="8355f-180">For more information, see [Using Statement](using-statement.md).</span></span>

## <a name="exception-argument"></a><span data-ttu-id="8355f-181">Argument d’exception</span><span class="sxs-lookup"><span data-stu-id="8355f-181">Exception argument</span></span>

<span data-ttu-id="8355f-182">L' `Catch` `exception` argument de bloc est une instance de la <xref:System.Exception> classe ou une classe qui dérive de la `Exception` classe.</span><span class="sxs-lookup"><span data-stu-id="8355f-182">The `Catch` block `exception` argument is an instance of the <xref:System.Exception> class or a class that derives from the `Exception` class.</span></span> <span data-ttu-id="8355f-183">L' `Exception` instance de classe correspond à l’erreur qui s’est produite dans le `Try` bloc.</span><span class="sxs-lookup"><span data-stu-id="8355f-183">The `Exception` class instance corresponds to the error that occurred in the `Try` block.</span></span>

<span data-ttu-id="8355f-184">Les propriétés de l' `Exception` objet permettent d’identifier la cause et l’emplacement d’une exception.</span><span class="sxs-lookup"><span data-stu-id="8355f-184">The properties of the `Exception` object help to identify the cause and location of an exception.</span></span> <span data-ttu-id="8355f-185">Par exemple, la <xref:System.Exception.StackTrace%2A> propriété répertorie les méthodes appelées qui ont conduit à l’exception, ce qui vous permet de trouver où l’erreur s’est produite dans le code.</span><span class="sxs-lookup"><span data-stu-id="8355f-185">For example, the <xref:System.Exception.StackTrace%2A> property lists the called methods that led to the exception, helping you find where the error occurred in the code.</span></span> <span data-ttu-id="8355f-186"><xref:System.Exception.Message%2A>retourne un message qui décrit l’exception.</span><span class="sxs-lookup"><span data-stu-id="8355f-186"><xref:System.Exception.Message%2A> returns a message that describes the exception.</span></span> <span data-ttu-id="8355f-187"><xref:System.Exception.HelpLink%2A>retourne un lien vers un fichier d’aide associé.</span><span class="sxs-lookup"><span data-stu-id="8355f-187"><xref:System.Exception.HelpLink%2A> returns a link to an associated Help file.</span></span> <span data-ttu-id="8355f-188"><xref:System.Exception.InnerException%2A>retourne l' `Exception` objet qui a provoqué l’exception actuelle, ou retourne `Nothing` s’il n’y a pas d’objet d’origine `Exception` .</span><span class="sxs-lookup"><span data-stu-id="8355f-188"><xref:System.Exception.InnerException%2A> returns the `Exception` object that caused the current exception, or it returns `Nothing` if there is no original `Exception`.</span></span>

## <a name="considerations-when-using-a-trycatch-statement"></a><span data-ttu-id="8355f-189">Considérations à prendre en compte lors de l’utilisation d’un bloc try... Catch (instruction)</span><span class="sxs-lookup"><span data-stu-id="8355f-189">Considerations when using a Try…Catch statement</span></span>

<span data-ttu-id="8355f-190">Utilisez une `Try…Catch` instruction uniquement pour signaler l’occurrence d’événements de programme inattendus ou imprévus.</span><span class="sxs-lookup"><span data-stu-id="8355f-190">Use a `Try…Catch` statement only to signal the occurrence of unusual or unanticipated program events.</span></span> <span data-ttu-id="8355f-191">Les raisons sont les suivantes :</span><span class="sxs-lookup"><span data-stu-id="8355f-191">Reasons for this include the following:</span></span>

- <span data-ttu-id="8355f-192">L’interception des exceptions au moment de l’exécution crée une surcharge supplémentaire et est susceptible d’être plus lente que la pré-vérification pour éviter les exceptions.</span><span class="sxs-lookup"><span data-stu-id="8355f-192">Catching exceptions at runtime creates additional overhead, and is likely to be slower than pre-checking to avoid exceptions.</span></span>

- <span data-ttu-id="8355f-193">Si un `Catch` bloc n’est pas géré correctement, l’exception peut ne pas être signalée correctement aux utilisateurs.</span><span class="sxs-lookup"><span data-stu-id="8355f-193">If a `Catch` block is not handled correctly, the exception might not be reported correctly to users.</span></span>

- <span data-ttu-id="8355f-194">La gestion des exceptions rend un programme plus complexe.</span><span class="sxs-lookup"><span data-stu-id="8355f-194">Exception handling makes a program more complex.</span></span>

<span data-ttu-id="8355f-195">Vous n’avez pas toujours besoin `Try…Catch` d’une instruction pour vérifier une condition qui est susceptible de se produire.</span><span class="sxs-lookup"><span data-stu-id="8355f-195">You do not always need a `Try…Catch` statement to check for a condition that is likely to occur.</span></span> <span data-ttu-id="8355f-196">L’exemple suivant vérifie si un fichier existe avant d’essayer de l’ouvrir.</span><span class="sxs-lookup"><span data-stu-id="8355f-196">The following example checks whether a file exists before trying to open it.</span></span> <span data-ttu-id="8355f-197">Cela réduit le besoin d’intercepter une exception levée par la <xref:System.IO.File.OpenText%2A> méthode.</span><span class="sxs-lookup"><span data-stu-id="8355f-197">This reduces the need for catching an exception thrown by the <xref:System.IO.File.OpenText%2A> method.</span></span>

[!code-vb[VbVbalrStatements#94](~/samples/snippets/visualbasic/VS_Snippets_VBCSharp/VbVbalrStatements/VB/Class1.vb#94)]

<span data-ttu-id="8355f-198">Assurez-vous que le code des `Catch` blocs peut signaler correctement les exceptions aux utilisateurs, que ce soit via une journalisation thread-safe ou des messages appropriés.</span><span class="sxs-lookup"><span data-stu-id="8355f-198">Ensure that code in `Catch` blocks can properly report exceptions to users, whether through thread-safe logging or appropriate messages.</span></span> <span data-ttu-id="8355f-199">Sinon, les exceptions peuvent rester inconnues.</span><span class="sxs-lookup"><span data-stu-id="8355f-199">Otherwise, exceptions might remain unknown.</span></span>

## <a name="async-methods"></a><span data-ttu-id="8355f-200">Méthodes Async</span><span class="sxs-lookup"><span data-stu-id="8355f-200">Async methods</span></span>

<span data-ttu-id="8355f-201">Si vous marquez une méthode avec le modificateur [Async](../modifiers/async.md) , vous pouvez utiliser l’opérateur [await](../operators/await-operator.md) dans la méthode.</span><span class="sxs-lookup"><span data-stu-id="8355f-201">If you mark a method with the [Async](../modifiers/async.md) modifier, you can use the [Await](../operators/await-operator.md) operator in the method.</span></span> <span data-ttu-id="8355f-202">Une instruction avec l' `Await` opérateur interrompt l’exécution de la méthode jusqu’à ce que la tâche attendue se termine.</span><span class="sxs-lookup"><span data-stu-id="8355f-202">A statement with the `Await` operator suspends execution of the method until the awaited task completes.</span></span> <span data-ttu-id="8355f-203">La tâche représente un travail en cours.</span><span class="sxs-lookup"><span data-stu-id="8355f-203">The task represents ongoing work.</span></span> <span data-ttu-id="8355f-204">Lorsque la tâche associée à l’opérateur se `Await` termine, l’exécution reprend dans la même méthode.</span><span class="sxs-lookup"><span data-stu-id="8355f-204">When the task that's associated with the `Await` operator finishes, execution resumes in the same method.</span></span> <span data-ttu-id="8355f-205">Pour plus d’informations, consultez [Control flow in Async Programs](../../programming-guide/concepts/async/control-flow-in-async-programs.md).</span><span class="sxs-lookup"><span data-stu-id="8355f-205">For more information, see [Control Flow in Async Programs](../../programming-guide/concepts/async/control-flow-in-async-programs.md).</span></span>

<span data-ttu-id="8355f-206">Une tâche retournée par une méthode Async peut se terminer par un état d’erreur, ce qui indique qu’elle s’est terminée en raison d’une exception non gérée.</span><span class="sxs-lookup"><span data-stu-id="8355f-206">A task returned by an Async method may end in a faulted state, indicating that it completed due to an unhandled exception.</span></span> <span data-ttu-id="8355f-207">Une tâche peut également se terminer par un état annulé, ce qui entraîne `OperationCanceledException` la levée d’une exception dans l’expression await.</span><span class="sxs-lookup"><span data-stu-id="8355f-207">A task may also end in a canceled state, which results in an `OperationCanceledException` being thrown out of the await expression.</span></span> <span data-ttu-id="8355f-208">Pour intercepter l’un ou l’autre type d’exception, placez l' `Await` expression associée à la tâche dans un `Try` bloc, puis interceptez l’exception dans le `Catch` bloc.</span><span class="sxs-lookup"><span data-stu-id="8355f-208">To catch either type of exception, place the `Await` expression that's associated with the task in a `Try` block, and catch the exception in the `Catch` block.</span></span> <span data-ttu-id="8355f-209">Un exemple est fourni plus loin dans cette rubrique.</span><span class="sxs-lookup"><span data-stu-id="8355f-209">An example is provided later in this topic.</span></span>

<span data-ttu-id="8355f-210">Une tâche peut être dans un état d’erreur, car plusieurs exceptions étaient responsables de son erreur.</span><span class="sxs-lookup"><span data-stu-id="8355f-210">A task can be in a faulted state because multiple exceptions were responsible for its faulting.</span></span> <span data-ttu-id="8355f-211">Par exemple, la tâche peut être le résultat d'un appel à <xref:System.Threading.Tasks.Task.WhenAll%2A?displayProperty=nameWithType>.</span><span class="sxs-lookup"><span data-stu-id="8355f-211">For example, the task might be the result of a call to <xref:System.Threading.Tasks.Task.WhenAll%2A?displayProperty=nameWithType>.</span></span> <span data-ttu-id="8355f-212">Lorsque vous attendez une telle tâche, l’exception interceptée n’est qu’une des exceptions, et vous ne pouvez pas prédire l’exception qui sera interceptée.</span><span class="sxs-lookup"><span data-stu-id="8355f-212">When you await such a task, the caught exception is only one of the exceptions, and you can't predict which exception will be caught.</span></span> <span data-ttu-id="8355f-213">Un exemple est fourni plus loin dans cette rubrique.</span><span class="sxs-lookup"><span data-stu-id="8355f-213">An example is provided later in this topic.</span></span>

<span data-ttu-id="8355f-214">Une `Await` expression ne peut pas se trouver à l’intérieur d’un `Catch` bloc ou d’un `Finally` bloc.</span><span class="sxs-lookup"><span data-stu-id="8355f-214">An `Await` expression can't be inside a `Catch` block or `Finally` block.</span></span>

## <a name="iterators"></a><span data-ttu-id="8355f-215">Iterators</span><span class="sxs-lookup"><span data-stu-id="8355f-215">Iterators</span></span>

<span data-ttu-id="8355f-216">Une fonction ou un `Get` accesseur d’itérateur effectue une itération personnalisée sur une collection.</span><span class="sxs-lookup"><span data-stu-id="8355f-216">An iterator function or `Get` accessor performs a custom iteration over a collection.</span></span> <span data-ttu-id="8355f-217">Un itérateur utilise une instruction [yield](yield-statement.md) pour retourner chaque élément de la collection un par un.</span><span class="sxs-lookup"><span data-stu-id="8355f-217">An iterator uses a [Yield](yield-statement.md) statement to return each element of the collection one at a time.</span></span> <span data-ttu-id="8355f-218">Vous appelez une fonction d’itérateur à l’aide [d’un pour chaque... Instruction suivante](for-each-next-statement.md).</span><span class="sxs-lookup"><span data-stu-id="8355f-218">You call an iterator function by using a [For Each...Next Statement](for-each-next-statement.md).</span></span>

<span data-ttu-id="8355f-219">Une `Yield` instruction peut se trouver à l’intérieur d’un `Try` bloc.</span><span class="sxs-lookup"><span data-stu-id="8355f-219">A `Yield` statement can be inside a `Try` block.</span></span> <span data-ttu-id="8355f-220">Un `Try` bloc qui contient une `Yield` instruction peut avoir des `Catch` blocs et peut avoir un `Finally` bloc.</span><span class="sxs-lookup"><span data-stu-id="8355f-220">A `Try` block that contains a `Yield` statement can have `Catch` blocks, and can have a `Finally` block.</span></span> <span data-ttu-id="8355f-221">Pour obtenir un exemple, consultez la section « blocs try dans Visual Basic » d' [itérateurs](../../programming-guide/concepts/iterators.md) .</span><span class="sxs-lookup"><span data-stu-id="8355f-221">See the "Try Blocks in Visual Basic" section of [Iterators](../../programming-guide/concepts/iterators.md) for an example.</span></span>

<span data-ttu-id="8355f-222">Une `Yield` instruction ne peut pas être à l’intérieur d’un `Catch` bloc ou d’un `Finally` bloc.</span><span class="sxs-lookup"><span data-stu-id="8355f-222">A `Yield` statement cannot be inside a `Catch` block or a `Finally` block.</span></span>

<span data-ttu-id="8355f-223">Si le `For Each` corps (en dehors de la fonction d’itérateur) lève une exception, un `Catch` bloc de la fonction d’itérateur n’est pas exécuté, mais un `Finally` bloc dans la fonction d’itérateur est exécuté.</span><span class="sxs-lookup"><span data-stu-id="8355f-223">If the `For Each` body (outside of the iterator function) throws an exception, a `Catch` block in the iterator function is not executed, but a `Finally` block in the iterator function is executed.</span></span> <span data-ttu-id="8355f-224">Un `Catch` bloc à l’intérieur d’une fonction d’itérateur intercepte uniquement les exceptions qui se produisent à l’intérieur de la fonction Iterator.</span><span class="sxs-lookup"><span data-stu-id="8355f-224">A `Catch` block inside an iterator function catches only exceptions that occur inside the iterator function.</span></span>

## <a name="partial-trust-situations"></a><span data-ttu-id="8355f-225">Situations de confiance partielle</span><span class="sxs-lookup"><span data-stu-id="8355f-225">Partial-trust situations</span></span>

<span data-ttu-id="8355f-226">Dans les situations de confiance partielle, telles qu’une application hébergée sur un partage réseau, `Try...Catch...Finally` n’intercepte pas les exceptions de sécurité qui se produisent avant l’appel de la méthode qui contient l’appel.</span><span class="sxs-lookup"><span data-stu-id="8355f-226">In partial-trust situations, such as an application hosted on a network share, `Try...Catch...Finally` does not catch security exceptions that occur before the method that contains the call is invoked.</span></span> <span data-ttu-id="8355f-227">L’exemple suivant, quand vous le placez sur un partage de serveur et que vous exécutez à partir de là, génère l’erreur « System. Security. SecurityException : échec de la demande ».</span><span class="sxs-lookup"><span data-stu-id="8355f-227">The following example, when you put it on a server share and run from there, produces the error "System.Security.SecurityException: Request Failed."</span></span> <span data-ttu-id="8355f-228">Pour plus d’informations sur les exceptions de sécurité, consultez la <xref:System.Security.SecurityException> classe.</span><span class="sxs-lookup"><span data-stu-id="8355f-228">For more information about security exceptions, see the <xref:System.Security.SecurityException> class.</span></span>

[!code-vb[VbVbalrStatements#85](~/samples/snippets/visualbasic/VS_Snippets_VBCSharp/VbVbalrStatements/VB/Class1.vb#85)]

<span data-ttu-id="8355f-229">Dans une telle situation de confiance partielle, vous devez placer l' `Process.Start` instruction dans un distinct `Sub` .</span><span class="sxs-lookup"><span data-stu-id="8355f-229">In such a partial-trust situation, you have to put the `Process.Start` statement in a separate `Sub`.</span></span> <span data-ttu-id="8355f-230">L’appel initial à l' `Sub` opération échoue.</span><span class="sxs-lookup"><span data-stu-id="8355f-230">The initial call to the `Sub` will fail.</span></span> <span data-ttu-id="8355f-231">Cela permet `Try...Catch` à de l’intercepter avant `Sub` que le qui contient `Process.Start` ne démarre et que l’exception de sécurité soit produite.</span><span class="sxs-lookup"><span data-stu-id="8355f-231">This enables `Try...Catch` to catch it before the `Sub` that contains `Process.Start` is started and the security exception produced.</span></span>

## <a name="examples"></a><span data-ttu-id="8355f-232">Exemples</span><span class="sxs-lookup"><span data-stu-id="8355f-232">Examples</span></span>

### <a name="the-structure-of-trycatchfinally"></a><span data-ttu-id="8355f-233">Structure de try... Catch... Suivie</span><span class="sxs-lookup"><span data-stu-id="8355f-233">The structure of Try...Catch...Finally</span></span>

<span data-ttu-id="8355f-234">L’exemple suivant illustre la structure de l' `Try...Catch...Finally` instruction.</span><span class="sxs-lookup"><span data-stu-id="8355f-234">The following example illustrates the structure of the `Try...Catch...Finally` statement.</span></span>

[!code-vb[VbVbalrStatements#86](~/samples/snippets/visualbasic/VS_Snippets_VBCSharp/VbVbalrStatements/VB/Class1.vb#86)]  

### <a name="exception-in-a-method-called-from-a-try-block"></a><span data-ttu-id="8355f-235">Exception dans une méthode appelée à partir d’un bloc try</span><span class="sxs-lookup"><span data-stu-id="8355f-235">Exception in a method called from a Try block</span></span>

<span data-ttu-id="8355f-236">Dans l’exemple suivant, la `CreateException` méthode lève une exception `NullReferenceException` .</span><span class="sxs-lookup"><span data-stu-id="8355f-236">In the following example, the `CreateException` method throws a `NullReferenceException`.</span></span> <span data-ttu-id="8355f-237">Le code qui génère l’exception n’est pas dans un `Try` bloc.</span><span class="sxs-lookup"><span data-stu-id="8355f-237">The code that generates the exception is not in a `Try` block.</span></span> <span data-ttu-id="8355f-238">Par conséquent, la `CreateException` méthode ne gère pas l’exception.</span><span class="sxs-lookup"><span data-stu-id="8355f-238">Therefore, the `CreateException` method does not handle the exception.</span></span> <span data-ttu-id="8355f-239">La `RunSample` méthode gère l’exception, car l’appel à la `CreateException` méthode se trouve dans un `Try` bloc.</span><span class="sxs-lookup"><span data-stu-id="8355f-239">The `RunSample` method does handle the exception because the call to the `CreateException` method is in a `Try` block.</span></span>

<span data-ttu-id="8355f-240">L’exemple comprend `Catch` des instructions pour plusieurs types d’exceptions, classées du plus spécifique au plus général.</span><span class="sxs-lookup"><span data-stu-id="8355f-240">The example includes `Catch` statements for several types of exceptions, ordered from the most specific to the most general.</span></span>

[!code-vb[VbVbalrStatements#91](~/samples/snippets/visualbasic/VS_Snippets_VBCSharp/VbVbalrStatements/VB/Class1.vb#91)]

### <a name="the-catch-when-statement"></a><span data-ttu-id="8355f-241">Instruction catch when</span><span class="sxs-lookup"><span data-stu-id="8355f-241">The Catch When statement</span></span>

<span data-ttu-id="8355f-242">L’exemple suivant montre comment utiliser une `Catch When` instruction pour filtrer sur une expression conditionnelle.</span><span class="sxs-lookup"><span data-stu-id="8355f-242">The following example shows how to use a `Catch When` statement to filter on a conditional expression.</span></span> <span data-ttu-id="8355f-243">Si l’expression conditionnelle a la valeur `True` , le code du `Catch` bloc s’exécute.</span><span class="sxs-lookup"><span data-stu-id="8355f-243">If the conditional expression evaluates to `True`, the code in the `Catch` block runs.</span></span>

[!code-vb[VbVbalrStatements#92](~/samples/snippets/visualbasic/VS_Snippets_VBCSharp/VbVbalrStatements/VB/Class1.vb#92)]

### <a name="nested-try-statements"></a><span data-ttu-id="8355f-244">Instructions Try imbriquées</span><span class="sxs-lookup"><span data-stu-id="8355f-244">Nested Try statements</span></span>

<span data-ttu-id="8355f-245">L’exemple suivant contient une `Try…Catch` instruction contenue dans un `Try` bloc.</span><span class="sxs-lookup"><span data-stu-id="8355f-245">The following example has a `Try…Catch` statement that is contained in a `Try` block.</span></span> <span data-ttu-id="8355f-246">Le `Catch` bloc interne lève une exception dont `InnerException` la propriété a la valeur de l’exception d’origine.</span><span class="sxs-lookup"><span data-stu-id="8355f-246">The inner `Catch` block throws an exception that has its `InnerException` property set to the original exception.</span></span> <span data-ttu-id="8355f-247">Le `Catch` bloc externe signale sa propre exception et l’exception interne.</span><span class="sxs-lookup"><span data-stu-id="8355f-247">The outer `Catch` block reports its own exception and the inner exception.</span></span>

[!code-vb[VbVbalrStatements#93](~/samples/snippets/visualbasic/VS_Snippets_VBCSharp/VbVbalrStatements/VB/Class1.vb#93)]

### <a name="exception-handling-for-async-methods"></a><span data-ttu-id="8355f-248">Gestion des exceptions pour les méthodes Async</span><span class="sxs-lookup"><span data-stu-id="8355f-248">Exception handling for async methods</span></span>

<span data-ttu-id="8355f-249">L'exemple suivant illustre la gestion des exceptions pour les méthodes async.</span><span class="sxs-lookup"><span data-stu-id="8355f-249">The following example illustrates exception handling for async methods.</span></span> <span data-ttu-id="8355f-250">Pour intercepter une exception qui s’applique à une tâche asynchrone, l' `Await` expression se trouve dans un `Try` bloc de l’appelant et l’exception est interceptée dans le `Catch` bloc.</span><span class="sxs-lookup"><span data-stu-id="8355f-250">To catch an exception that applies to an async task, the `Await` expression is in a `Try` block of the caller, and the exception is caught in the `Catch` block.</span></span>

<span data-ttu-id="8355f-251">Supprimez les marques de commentaire de la ligne `Throw New Exception` dans l'exemple pour illustrer la gestion des exceptions.</span><span class="sxs-lookup"><span data-stu-id="8355f-251">Uncomment the `Throw New Exception` line in the example to demonstrate exception handling.</span></span> <span data-ttu-id="8355f-252">L’exception est interceptée dans le `Catch` bloc, la propriété de la tâche `IsFaulted` a la valeur et la `True` propriété de la tâche `Exception.InnerException` a la valeur de l’exception.</span><span class="sxs-lookup"><span data-stu-id="8355f-252">The exception is caught in the `Catch` block, the task's `IsFaulted` property is set to `True`, and the task's `Exception.InnerException` property is set to the exception.</span></span>

<span data-ttu-id="8355f-253">Supprimez les marques de commentaire de la ligne `Throw New OperationCancelledException` pour montrer ce qui se passe quand vous annulez un processus asynchrone.</span><span class="sxs-lookup"><span data-stu-id="8355f-253">Uncomment the `Throw New OperationCancelledException` line to demonstrate what happens when you cancel an asynchronous process.</span></span> <span data-ttu-id="8355f-254">L’exception est interceptée dans le `Catch` bloc et la propriété de la tâche `IsCanceled` a la valeur `True` .</span><span class="sxs-lookup"><span data-stu-id="8355f-254">The exception is caught in the `Catch` block, and the task's `IsCanceled` property is set to `True`.</span></span> <span data-ttu-id="8355f-255">Toutefois, dans certaines conditions qui ne s’appliquent pas à cet exemple, `IsFaulted` a la valeur `True` et `IsCanceled` a la valeur `False` .</span><span class="sxs-lookup"><span data-stu-id="8355f-255">However, under some conditions that don't apply to this example, `IsFaulted` is set to `True` and `IsCanceled` is set to `False`.</span></span>

[!code-vb[csAsyncExceptions#1](~/samples/snippets/visualbasic/VS_Snippets_VBCSharp/csasyncexceptions/vb/class1.vb#1)]

### <a name="handling-multiple-exceptions-in-async-methods"></a><span data-ttu-id="8355f-256">Gestion de plusieurs exceptions dans les méthodes Async</span><span class="sxs-lookup"><span data-stu-id="8355f-256">Handling multiple exceptions in async methods</span></span>

<span data-ttu-id="8355f-257">L’exemple suivant illustre la gestion des exceptions quand plusieurs tâches peuvent entraîner plusieurs exceptions.</span><span class="sxs-lookup"><span data-stu-id="8355f-257">The following example illustrates exception handling where multiple tasks can result in multiple exceptions.</span></span> <span data-ttu-id="8355f-258">Le `Try` bloc a l' `Await` expression de la tâche qui a été <xref:System.Threading.Tasks.Task.WhenAll%2A?displayProperty=nameWithType> retournée.</span><span class="sxs-lookup"><span data-stu-id="8355f-258">The `Try` block has the `Await` expression for the task that <xref:System.Threading.Tasks.Task.WhenAll%2A?displayProperty=nameWithType> returned.</span></span> <span data-ttu-id="8355f-259">La tâche est terminée lorsque les trois tâches auxquelles <xref:System.Threading.Tasks.Task.WhenAll%2A?displayProperty=nameWithType> est appliqué sont terminées.</span><span class="sxs-lookup"><span data-stu-id="8355f-259">The task is complete when the three tasks to which <xref:System.Threading.Tasks.Task.WhenAll%2A?displayProperty=nameWithType> is applied are complete.</span></span>

<span data-ttu-id="8355f-260">Chacune de ces trois tâches provoque une exception.</span><span class="sxs-lookup"><span data-stu-id="8355f-260">Each of the three tasks causes an exception.</span></span> <span data-ttu-id="8355f-261">Le `Catch` bloc itère au sein des exceptions, qui se trouvent dans la `Exception.InnerExceptions` propriété de la tâche `Task.WhenAll` retournée.</span><span class="sxs-lookup"><span data-stu-id="8355f-261">The `Catch` block iterates through the exceptions, which are found in the `Exception.InnerExceptions` property of the task that `Task.WhenAll` returned.</span></span>

[!code-vb[csAsyncExceptions#3](~/samples/snippets/visualbasic/VS_Snippets_VBCSharp/csasyncexceptions/vb/class1.vb#3)]

## <a name="see-also"></a><span data-ttu-id="8355f-262">Voir aussi</span><span class="sxs-lookup"><span data-stu-id="8355f-262">See also</span></span>

- <xref:Microsoft.VisualBasic.Information.Err%2A>
- <xref:System.Exception>
- [<span data-ttu-id="8355f-263">Exit (instruction)</span><span class="sxs-lookup"><span data-stu-id="8355f-263">Exit Statement</span></span>](exit-statement.md)
- [<span data-ttu-id="8355f-264">On Error (instruction)</span><span class="sxs-lookup"><span data-stu-id="8355f-264">On Error Statement</span></span>](on-error-statement.md)
- [<span data-ttu-id="8355f-265">Bonnes pratiques pour l’utilisation des extraits de code</span><span class="sxs-lookup"><span data-stu-id="8355f-265">Best Practices for Using Code Snippets</span></span>](/visualstudio/ide/best-practices-for-using-code-snippets)
- [<span data-ttu-id="8355f-266">Gestion des exceptions</span><span class="sxs-lookup"><span data-stu-id="8355f-266">Exception Handling</span></span>](../../../standard/parallel-programming/exception-handling-task-parallel-library.md)
- [<span data-ttu-id="8355f-267">Throw (instruction)</span><span class="sxs-lookup"><span data-stu-id="8355f-267">Throw Statement</span></span>](throw-statement.md)
