---
title: Try... Catch... Instruction finally - Visual Basic
description: Apprenez à utiliser des exceptions avec Visual Basic instructions Try/Catch/Finally.
ms.date: 12/07/2018
f1_keywords:
- vb.Try...Catch...Finally
- vb.when
- vb.Finally
- vb.Catch
- vb.Try
helpviewer_keywords:
- Try...Catch...Finally statements
- Try statement [Visual Basic]
- try-catch exception handling, Try...Catch...Finally statements
- error handling, while running code
- Try statement [Visual Basic], Try...Catch...Finally
- Finally keyword [Visual Basic], Try...Catch...Finally
- Catch statement [Visual Basic]
- When keyword [Visual Basic]
- Visual Basic code, handling errors while running
- structured exception handling, Try...Catch...Finally statements
ms.assetid: d6488026-ccb3-42b8-a810-0d97b9d6472b
ms.custom: seodec18
ms.openlocfilehash: 126f20c86bb47e8002382e069ce6236600394aba
ms.sourcegitcommit: 8699383914c24a0df033393f55db3369db728a7b
ms.translationtype: MT
ms.contentlocale: fr-FR
ms.lasthandoff: 05/15/2019
ms.locfileid: "65638771"
---
# <a name="trycatchfinally-statement-visual-basic"></a><span data-ttu-id="7e364-103">Try...Catch...Finally, instruction (Visual Basic)</span><span class="sxs-lookup"><span data-stu-id="7e364-103">Try...Catch...Finally Statement (Visual Basic)</span></span>

<span data-ttu-id="7e364-104">Fournit un moyen de gérer certaines ou toutes les erreurs possibles qui peuvent se produire dans un bloc donné du code, tout code en cours d’exécution.</span><span class="sxs-lookup"><span data-stu-id="7e364-104">Provides a way to handle some or all possible errors that may occur in a given block of code, while still running code.</span></span>

## <a name="syntax"></a><span data-ttu-id="7e364-105">Syntaxe</span><span class="sxs-lookup"><span data-stu-id="7e364-105">Syntax</span></span>

```vb
Try
    [ tryStatements ]
    [ Exit Try ]
[ Catch [ exception [ As type ] ] [ When expression ]
    [ catchStatements ]
    [ Exit Try ] ]
[ Catch ... ]
[ Finally
    [ finallyStatements ] ]
End Try
```

## <a name="parts"></a><span data-ttu-id="7e364-106">Composants</span><span class="sxs-lookup"><span data-stu-id="7e364-106">Parts</span></span>

|<span data-ttu-id="7e364-107">Terme</span><span class="sxs-lookup"><span data-stu-id="7e364-107">Term</span></span>|<span data-ttu-id="7e364-108">Définition</span><span class="sxs-lookup"><span data-stu-id="7e364-108">Definition</span></span>|
|---|---|
|`tryStatements`|<span data-ttu-id="7e364-109">Facultatif.</span><span class="sxs-lookup"><span data-stu-id="7e364-109">Optional.</span></span> <span data-ttu-id="7e364-110">Instructions où une erreur peut se produire.</span><span class="sxs-lookup"><span data-stu-id="7e364-110">Statement(s) where an error can occur.</span></span> <span data-ttu-id="7e364-111">Il peut s'agir d'une instruction composée.</span><span class="sxs-lookup"><span data-stu-id="7e364-111">Can be a compound statement.</span></span>|
|`Catch`|<span data-ttu-id="7e364-112">Facultatif.</span><span class="sxs-lookup"><span data-stu-id="7e364-112">Optional.</span></span> <span data-ttu-id="7e364-113">Plusieurs `Catch` blocs autorisés.</span><span class="sxs-lookup"><span data-stu-id="7e364-113">Multiple `Catch` blocks permitted.</span></span> <span data-ttu-id="7e364-114">Si une exception se produit lors du traitement de la `Try` bloquer, chacun `Catch` instruction est examinée dans l’ordre textuel afin de déterminer si elle gère l’exception, avec `exception` représentant l’exception qui a été levée.</span><span class="sxs-lookup"><span data-stu-id="7e364-114">If an exception occurs when processing the `Try` block, each `Catch` statement is examined in textual order to determine whether it handles the exception, with `exception` representing the exception that has been thrown.</span></span>|
|`exception`|<span data-ttu-id="7e364-115">Facultatif.</span><span class="sxs-lookup"><span data-stu-id="7e364-115">Optional.</span></span> <span data-ttu-id="7e364-116">Tout nom de variable.</span><span class="sxs-lookup"><span data-stu-id="7e364-116">Any variable name.</span></span> <span data-ttu-id="7e364-117">La valeur initiale de l'argument `exception` est la valeur de l'erreur levée.</span><span class="sxs-lookup"><span data-stu-id="7e364-117">The initial value of `exception` is the value of the thrown error.</span></span> <span data-ttu-id="7e364-118">Utilisé avec `Catch` pour spécifier l’erreur interceptée.</span><span class="sxs-lookup"><span data-stu-id="7e364-118">Used with `Catch` to specify the error caught.</span></span> <span data-ttu-id="7e364-119">Si omis, la `Catch` instruction intercepte toute exception.</span><span class="sxs-lookup"><span data-stu-id="7e364-119">If omitted, the `Catch` statement catches any exception.</span></span>|
|`type`|<span data-ttu-id="7e364-120">Facultatif.</span><span class="sxs-lookup"><span data-stu-id="7e364-120">Optional.</span></span> <span data-ttu-id="7e364-121">Spécifie le type de filtre de la classe.</span><span class="sxs-lookup"><span data-stu-id="7e364-121">Specifies the type of class filter.</span></span> <span data-ttu-id="7e364-122">Si la valeur de `exception` est du type spécifié par `type` ou d’un type dérivé, l’identificateur est lié à l’objet exception.</span><span class="sxs-lookup"><span data-stu-id="7e364-122">If the value of `exception` is of the type specified by `type` or of a derived type, the identifier becomes bound to the exception object.</span></span>|
|`When`|<span data-ttu-id="7e364-123">Facultatif.</span><span class="sxs-lookup"><span data-stu-id="7e364-123">Optional.</span></span> <span data-ttu-id="7e364-124">Un `Catch` instruction avec un `When` clause intercepte les exceptions uniquement lorsque `expression` prend la valeur `True`.</span><span class="sxs-lookup"><span data-stu-id="7e364-124">A `Catch` statement with a `When` clause catches exceptions only when `expression` evaluates to `True`.</span></span> <span data-ttu-id="7e364-125">Un `When` clause est appliquée uniquement après la vérification du type de l’exception, et `expression` peut faire référence à l’identificateur qui représente l’exception.</span><span class="sxs-lookup"><span data-stu-id="7e364-125">A `When` clause is applied only after checking the type of the exception, and `expression` may refer to the identifier representing the exception.</span></span>|
|`expression`|<span data-ttu-id="7e364-126">Facultatif.</span><span class="sxs-lookup"><span data-stu-id="7e364-126">Optional.</span></span> <span data-ttu-id="7e364-127">Doit être implicitement convertible en `Boolean`.</span><span class="sxs-lookup"><span data-stu-id="7e364-127">Must be implicitly convertible to `Boolean`.</span></span> <span data-ttu-id="7e364-128">Toute expression qui décrit un filtre générique.</span><span class="sxs-lookup"><span data-stu-id="7e364-128">Any expression that describes a generic filter.</span></span> <span data-ttu-id="7e364-129">Généralement utilisé pour filtrer par numéro d’erreur.</span><span class="sxs-lookup"><span data-stu-id="7e364-129">Typically used to filter by error number.</span></span> <span data-ttu-id="7e364-130">Utilisé avec `When` mot clé pour spécifier les circonstances dans lesquelles l’erreur est interceptée.</span><span class="sxs-lookup"><span data-stu-id="7e364-130">Used with `When` keyword to specify circumstances under which the error is caught.</span></span>|
|`catchStatements`|<span data-ttu-id="7e364-131">Facultatif.</span><span class="sxs-lookup"><span data-stu-id="7e364-131">Optional.</span></span> <span data-ttu-id="7e364-132">Instructions permettant de gérer les erreurs qui se produisent dans associé `Try` bloc.</span><span class="sxs-lookup"><span data-stu-id="7e364-132">Statement(s) to handle errors that occur in the associated `Try` block.</span></span> <span data-ttu-id="7e364-133">Il peut s'agir d'une instruction composée.</span><span class="sxs-lookup"><span data-stu-id="7e364-133">Can be a compound statement.</span></span>|
|`Exit Try`|<span data-ttu-id="7e364-134">Facultatif.</span><span class="sxs-lookup"><span data-stu-id="7e364-134">Optional.</span></span> <span data-ttu-id="7e364-135">Mot clé qui décompose le `Try...Catch...Finally` structure.</span><span class="sxs-lookup"><span data-stu-id="7e364-135">Keyword that breaks out of the `Try...Catch...Finally` structure.</span></span> <span data-ttu-id="7e364-136">L’exécution reprend avec le code qui suit immédiatement la `End Try` instruction.</span><span class="sxs-lookup"><span data-stu-id="7e364-136">Execution resumes with the code immediately following the `End Try` statement.</span></span> <span data-ttu-id="7e364-137">La `Finally` instruction sera exécutée.</span><span class="sxs-lookup"><span data-stu-id="7e364-137">The `Finally` statement will still be executed.</span></span> <span data-ttu-id="7e364-138">Interdit dans `Finally` blocs.</span><span class="sxs-lookup"><span data-stu-id="7e364-138">Not allowed in `Finally` blocks.</span></span>|
|`Finally`|<span data-ttu-id="7e364-139">Facultatif.</span><span class="sxs-lookup"><span data-stu-id="7e364-139">Optional.</span></span> <span data-ttu-id="7e364-140">Un `Finally` bloc est toujours exécuté quand l’exécution quitte une partie de la `Try...Catch` instruction.</span><span class="sxs-lookup"><span data-stu-id="7e364-140">A `Finally` block is always executed when execution leaves any part of the `Try...Catch` statement.</span></span>|
|`finallyStatements`|<span data-ttu-id="7e364-141">Facultatif.</span><span class="sxs-lookup"><span data-stu-id="7e364-141">Optional.</span></span> <span data-ttu-id="7e364-142">Instructions qui sont exécutées une fois que tout autre traitement d’erreur s’est produite.</span><span class="sxs-lookup"><span data-stu-id="7e364-142">Statement(s) that are executed after all other error processing has occurred.</span></span>|
|`End Try`|<span data-ttu-id="7e364-143">Met fin à la `Try...Catch...Finally` structure.</span><span class="sxs-lookup"><span data-stu-id="7e364-143">Terminates the `Try...Catch...Finally` structure.</span></span>|

## <a name="remarks"></a><span data-ttu-id="7e364-144">Notes</span><span class="sxs-lookup"><span data-stu-id="7e364-144">Remarks</span></span>

<span data-ttu-id="7e364-145">Si vous pensez qu’une exception particulière se produise pendant une section particulière de code, placez le code dans un `Try` bloquer et utiliser un `Catch` bloc pour garder le contrôle et de gérer l’exception si elle se produit.</span><span class="sxs-lookup"><span data-stu-id="7e364-145">If you expect that a particular exception might occur during a particular section of code, put the code in a `Try` block and use a `Catch` block to retain control and handle the exception if it occurs.</span></span>

<span data-ttu-id="7e364-146">Un `Try…Catch` instruction se compose d’un `Try` bloc suivie d’une ou plusieurs `Catch` clauses qui spécifient des gestionnaires pour différentes exceptions.</span><span class="sxs-lookup"><span data-stu-id="7e364-146">A `Try…Catch` statement consists of a `Try` block followed by one or more `Catch` clauses, which specify handlers for various exceptions.</span></span> <span data-ttu-id="7e364-147">Lorsqu’une exception est levée dans un `Try` bloquer, Visual Basic recherche le `Catch` instruction qui gère l’exception.</span><span class="sxs-lookup"><span data-stu-id="7e364-147">When an exception is thrown in a `Try` block, Visual Basic looks for the `Catch` statement that handles the exception.</span></span> <span data-ttu-id="7e364-148">Si une correspondance `Catch` instruction n’est pas trouvée, Visual Basic examine la méthode qui a appelé la méthode actuelle, et ainsi de suite la pile des appels.</span><span class="sxs-lookup"><span data-stu-id="7e364-148">If a matching `Catch` statement is not found, Visual Basic examines the method that called the current method, and so on up the call stack.</span></span> <span data-ttu-id="7e364-149">Si aucun `Catch` bloc est trouvé, Visual Basic affiche un message d’exception non prise en charge pour l’utilisateur et arrête l’exécution du programme.</span><span class="sxs-lookup"><span data-stu-id="7e364-149">If no `Catch` block is found, Visual Basic displays an unhandled exception message to the user and stops execution of the program.</span></span>

<span data-ttu-id="7e364-150">Vous pouvez utiliser plusieurs `Catch` instruction dans un `Try…Catch` instruction.</span><span class="sxs-lookup"><span data-stu-id="7e364-150">You can use more than one `Catch` statement in a `Try…Catch` statement.</span></span> <span data-ttu-id="7e364-151">Dans ce cas, l’ordre de la `Catch` clauses est important, car ils sont examinés dans l’ordre.</span><span class="sxs-lookup"><span data-stu-id="7e364-151">If you do this, the order of the `Catch` clauses is significant because they are examined in order.</span></span> <span data-ttu-id="7e364-152">Interceptez les exceptions plus spécifiques avant les moins spécifiques.</span><span class="sxs-lookup"><span data-stu-id="7e364-152">Catch the more specific exceptions before the less specific ones.</span></span>

<span data-ttu-id="7e364-153">Ce qui suit `Catch` conditions de l’instruction sont les moins spécifiques et intercepte toutes les exceptions qui dérivent de la <xref:System.Exception> classe.</span><span class="sxs-lookup"><span data-stu-id="7e364-153">The following `Catch` statement conditions are the least specific, and will catch all exceptions that derive from the <xref:System.Exception> class.</span></span> <span data-ttu-id="7e364-154">Vous devez normalement utiliser une de ces variations comme dernier `Catch` bloquer le `Try...Catch...Finally` structure, après l’interception de toutes les exceptions spécifiques que vous attendez.</span><span class="sxs-lookup"><span data-stu-id="7e364-154">You should ordinarily use one of these variations as the last `Catch` block in the `Try...Catch...Finally` structure, after catching all the specific exceptions you expect.</span></span> <span data-ttu-id="7e364-155">Flux de contrôle ne peut jamais atteindre un `Catch` bloc qui suit une de ces variantes.</span><span class="sxs-lookup"><span data-stu-id="7e364-155">Control flow can never reach a `Catch` block that follows either of these variations.</span></span>

- <span data-ttu-id="7e364-156">Le `type` est `Exception`, par exemple : `Catch ex As Exception`</span><span class="sxs-lookup"><span data-stu-id="7e364-156">The `type` is `Exception`, for example: `Catch ex As Exception`</span></span>

- <span data-ttu-id="7e364-157">L’instruction n’a aucun `exception` variable, par exemple : `Catch`</span><span class="sxs-lookup"><span data-stu-id="7e364-157">The statement has no `exception` variable, for example: `Catch`</span></span>

<span data-ttu-id="7e364-158">Quand un `Try…Catch…Finally` instruction est imbriquée dans une autre `Try` bloc, Visual Basic examine tout d’abord chaque `Catch` instruction dans la plus intérieure `Try` bloc.</span><span class="sxs-lookup"><span data-stu-id="7e364-158">When a `Try…Catch…Finally` statement is nested in another `Try` block, Visual Basic first examines each `Catch` statement in the innermost `Try` block.</span></span> <span data-ttu-id="7e364-159">Si aucune correspondance `Catch` instruction est trouvée, la recherche se poursuit à le `Catch` instructions d’externe `Try…Catch…Finally` bloc.</span><span class="sxs-lookup"><span data-stu-id="7e364-159">If no matching `Catch` statement is found, the search proceeds to the `Catch` statements of the outer `Try…Catch…Finally` block.</span></span>

<span data-ttu-id="7e364-160">Les variables locales à partir d’un `Try` bloc ne sont pas disponibles dans un `Catch` bloqué, car ils sont des blocs séparés.</span><span class="sxs-lookup"><span data-stu-id="7e364-160">Local variables from a `Try` block are not available in a `Catch` block because they are separate blocks.</span></span> <span data-ttu-id="7e364-161">Si vous souhaitez utiliser une variable dans plusieurs blocs, déclarez la variable en dehors de la `Try...Catch...Finally` structure.</span><span class="sxs-lookup"><span data-stu-id="7e364-161">If you want to use a variable in more than one block, declare the variable outside the `Try...Catch...Finally` structure.</span></span>

> [!TIP]
> <span data-ttu-id="7e364-162">La `Try…Catch…Finally` instruction est disponible en tant qu’un extrait de code IntelliSense.</span><span class="sxs-lookup"><span data-stu-id="7e364-162">The `Try…Catch…Finally` statement is available as an IntelliSense code snippet.</span></span> <span data-ttu-id="7e364-163">Dans le Gestionnaire des extraits de Code, développez **modèles de Code - If, For Each, Try Catch, propriété, etc.**, puis **(Exceptions) de gestion des erreurs**.</span><span class="sxs-lookup"><span data-stu-id="7e364-163">In the Code Snippets Manager, expand **Code Patterns - If, For Each, Try Catch, Property, etc**, and then **Error Handling (Exceptions)**.</span></span> <span data-ttu-id="7e364-164">Pour plus d’informations, consultez [Extraits de code](/visualstudio/ide/code-snippets).</span><span class="sxs-lookup"><span data-stu-id="7e364-164">For more information, see [Code Snippets](/visualstudio/ide/code-snippets).</span></span>

## <a name="finally-block"></a><span data-ttu-id="7e364-165">Bloc finally</span><span class="sxs-lookup"><span data-stu-id="7e364-165">Finally block</span></span>

<span data-ttu-id="7e364-166">Si vous avez une ou plusieurs instructions qui doivent s’exécuter avant de quitter le `Try` structure, utilisez un `Finally` bloc.</span><span class="sxs-lookup"><span data-stu-id="7e364-166">If you have one or more statements that must run before you exit the `Try` structure, use a `Finally` block.</span></span> <span data-ttu-id="7e364-167">Le contrôle passe à la `Finally` bloquer juste avant de sortir de la `Try…Catch` structure.</span><span class="sxs-lookup"><span data-stu-id="7e364-167">Control passes to the `Finally` block just before it passes out of the `Try…Catch` structure.</span></span> <span data-ttu-id="7e364-168">Cela est vrai même si une exception se produit n’importe où à l’intérieur de la `Try` structure.</span><span class="sxs-lookup"><span data-stu-id="7e364-168">This is true even if an exception occurs anywhere inside the `Try` structure.</span></span>

<span data-ttu-id="7e364-169">Un `Finally` bloc est utile pour l’exécution de tout code qui doit s’exécuter même s’il existe une exception.</span><span class="sxs-lookup"><span data-stu-id="7e364-169">A `Finally` block is useful for running any code that must execute even if there is an exception.</span></span> <span data-ttu-id="7e364-170">Le contrôle est passé à la `Finally` bloc quelle que soit la façon dont le `Try...Catch` bloquer se ferme.</span><span class="sxs-lookup"><span data-stu-id="7e364-170">Control is passed to the `Finally` block regardless of how the `Try...Catch` block exits.</span></span>

<span data-ttu-id="7e364-171">Le code dans un `Finally` bloque s’exécute même si votre code rencontre une `Return` instruction dans un `Try` ou `Catch` bloc.</span><span class="sxs-lookup"><span data-stu-id="7e364-171">The code in a `Finally` block runs even if your code encounters a `Return` statement in a `Try` or `Catch` block.</span></span> <span data-ttu-id="7e364-172">Contrôle ne passe pas d’un `Try` ou `Catch` bloquer correspondant `Finally` bloquer dans les cas suivants :</span><span class="sxs-lookup"><span data-stu-id="7e364-172">Control does not pass from a `Try` or `Catch` block to the corresponding `Finally` block in the following cases:</span></span>

- <span data-ttu-id="7e364-173">Un [instruction End](end-statement.md) est rencontré dans le `Try` ou `Catch` bloc.</span><span class="sxs-lookup"><span data-stu-id="7e364-173">An [End Statement](end-statement.md) is encountered in the `Try` or `Catch` block.</span></span>

- <span data-ttu-id="7e364-174">Un <xref:System.StackOverflowException> est levée dans le `Try` ou `Catch` bloc.</span><span class="sxs-lookup"><span data-stu-id="7e364-174">A <xref:System.StackOverflowException> is thrown in the `Try` or `Catch` block.</span></span>

<span data-ttu-id="7e364-175">Il n’est pas valide pour transférer explicitement l’exécution dans un `Finally` bloc.</span><span class="sxs-lookup"><span data-stu-id="7e364-175">It is not valid to explicitly transfer execution into a `Finally` block.</span></span> <span data-ttu-id="7e364-176">Transfert de l’exécution hors d’un `Finally` bloc n’est pas valide, sauf via une exception.</span><span class="sxs-lookup"><span data-stu-id="7e364-176">Transferring execution out of a `Finally` block is not valid, except through an exception.</span></span>

<span data-ttu-id="7e364-177">Si un `Try` instruction ne contient-elle pas au moins un `Catch` bloc, il doit contenir un `Finally` bloc.</span><span class="sxs-lookup"><span data-stu-id="7e364-177">If a `Try` statement does not contain at least one `Catch` block, it must contain a `Finally` block.</span></span>

> [!TIP]
> <span data-ttu-id="7e364-178">Si vous n’avez pas intercepter des exceptions spécifiques, le `Using` instruction se comporte comme un `Try…Finally` bloc et garantit l’élimination des ressources, quel que soit la manière dont vous quittez le bloc.</span><span class="sxs-lookup"><span data-stu-id="7e364-178">If you do not have to catch specific exceptions, the `Using` statement behaves like a `Try…Finally` block, and guarantees disposal of the resources, regardless of how you exit the block.</span></span> <span data-ttu-id="7e364-179">Cela est vrai même avec une exception non gérée.</span><span class="sxs-lookup"><span data-stu-id="7e364-179">This is true even with an unhandled exception.</span></span> <span data-ttu-id="7e364-180">Pour plus d’informations, consultez [using, instruction](using-statement.md).</span><span class="sxs-lookup"><span data-stu-id="7e364-180">For more information, see [Using Statement](using-statement.md).</span></span>

## <a name="exception-argument"></a><span data-ttu-id="7e364-181">Argument d’exception</span><span class="sxs-lookup"><span data-stu-id="7e364-181">Exception argument</span></span>

<span data-ttu-id="7e364-182">Le `Catch` bloc `exception` argument est une instance de la <xref:System.Exception> classe ou une classe qui dérive de la `Exception` classe.</span><span class="sxs-lookup"><span data-stu-id="7e364-182">The `Catch` block `exception` argument is an instance of the <xref:System.Exception> class or a class that derives from the `Exception` class.</span></span> <span data-ttu-id="7e364-183">Le `Exception` instance de classe correspond à l’erreur qui s’est produite dans le `Try` bloc.</span><span class="sxs-lookup"><span data-stu-id="7e364-183">The `Exception` class instance corresponds to the error that occurred in the `Try` block.</span></span>

<span data-ttu-id="7e364-184">Les propriétés de la `Exception` aide à identifier la cause et l’emplacement d’une exception de l’objet.</span><span class="sxs-lookup"><span data-stu-id="7e364-184">The properties of the `Exception` object help to identify the cause and location of an exception.</span></span> <span data-ttu-id="7e364-185">Par exemple, le <xref:System.Exception.StackTrace%2A> propriété répertorie les méthodes appelées qui a conduit à l’exception, ce qui vous aide à trouver où l’erreur s’est produite dans le code.</span><span class="sxs-lookup"><span data-stu-id="7e364-185">For example, the <xref:System.Exception.StackTrace%2A> property lists the called methods that led to the exception, helping you find where the error occurred in the code.</span></span> <span data-ttu-id="7e364-186"><xref:System.Exception.Message%2A> Retourne un message qui décrit l’exception.</span><span class="sxs-lookup"><span data-stu-id="7e364-186"><xref:System.Exception.Message%2A> returns a message that describes the exception.</span></span> <span data-ttu-id="7e364-187"><xref:System.Exception.HelpLink%2A> Renvoie un lien vers un fichier d’aide associé.</span><span class="sxs-lookup"><span data-stu-id="7e364-187"><xref:System.Exception.HelpLink%2A> returns a link to an associated Help file.</span></span> <span data-ttu-id="7e364-188"><xref:System.Exception.InnerException%2A> Retourne le `Exception` objet qui a provoqué l’exception actuelle, ou elle retourne `Nothing` s’il n’existe aucun original `Exception`.</span><span class="sxs-lookup"><span data-stu-id="7e364-188"><xref:System.Exception.InnerException%2A> returns the `Exception` object that caused the current exception, or it returns `Nothing` if there is no original `Exception`.</span></span>

## <a name="considerations-when-using-a-trycatch-statement"></a><span data-ttu-id="7e364-189">Considérations sur l’utilisation d’un bloc Try... Catch, instruction</span><span class="sxs-lookup"><span data-stu-id="7e364-189">Considerations when using a Try…Catch statement</span></span>

<span data-ttu-id="7e364-190">Utilisez un `Try…Catch` instruction uniquement pour signaler la présence d’événements inhabituels ou imprévus.</span><span class="sxs-lookup"><span data-stu-id="7e364-190">Use a `Try…Catch` statement only to signal the occurrence of unusual or unanticipated program events.</span></span> <span data-ttu-id="7e364-191">Pour cela les raisons suivantes :</span><span class="sxs-lookup"><span data-stu-id="7e364-191">Reasons for this include the following:</span></span>

- <span data-ttu-id="7e364-192">Interception des exceptions lors de l’exécution crée une charge supplémentaire et est susceptible d’être plus lent que pré-vérification pour éviter les exceptions.</span><span class="sxs-lookup"><span data-stu-id="7e364-192">Catching exceptions at runtime creates additional overhead, and is likely to be slower than pre-checking to avoid exceptions.</span></span>

- <span data-ttu-id="7e364-193">Si un `Catch` bloc n’est pas traitée correctement, l’exception peuvent ne pas être déclarée correctement pour les utilisateurs.</span><span class="sxs-lookup"><span data-stu-id="7e364-193">If a `Catch` block is not handled correctly, the exception might not be reported correctly to users.</span></span>

- <span data-ttu-id="7e364-194">Gestion des exceptions rend plus complexe.</span><span class="sxs-lookup"><span data-stu-id="7e364-194">Exception handling makes a program more complex.</span></span>

<span data-ttu-id="7e364-195">Vous n’avez pas toujours besoin un `Try…Catch` instruction pour vérifier une condition qui est susceptible de se produire.</span><span class="sxs-lookup"><span data-stu-id="7e364-195">You do not always need a `Try…Catch` statement to check for a condition that is likely to occur.</span></span> <span data-ttu-id="7e364-196">L’exemple suivant vérifie l’existence d’un fichier avant d’essayer de l’ouvrir.</span><span class="sxs-lookup"><span data-stu-id="7e364-196">The following example checks whether a file exists before trying to open it.</span></span> <span data-ttu-id="7e364-197">Cela réduit la nécessité d’intercepter une exception levée par le <xref:System.IO.File.OpenText%2A> (méthode).</span><span class="sxs-lookup"><span data-stu-id="7e364-197">This reduces the need for catching an exception thrown by the <xref:System.IO.File.OpenText%2A> method.</span></span>

[!code-vb[VbVbalrStatements#94](~/samples/snippets/visualbasic/VS_Snippets_VBCSharp/VbVbalrStatements/VB/Class1.vb#94)]

<span data-ttu-id="7e364-198">Assurez-vous que le code de `Catch` blocs peuvent correctement signaler les exceptions aux utilisateurs, via la journalisation thread-safe ou les messages appropriés.</span><span class="sxs-lookup"><span data-stu-id="7e364-198">Ensure that code in `Catch` blocks can properly report exceptions to users, whether through thread-safe logging or appropriate messages.</span></span> <span data-ttu-id="7e364-199">Sinon, les exceptions pourraient rester inconnues.</span><span class="sxs-lookup"><span data-stu-id="7e364-199">Otherwise, exceptions might remain unknown.</span></span>

## <a name="async-methods"></a><span data-ttu-id="7e364-200">Méthodes Async</span><span class="sxs-lookup"><span data-stu-id="7e364-200">Async methods</span></span>

<span data-ttu-id="7e364-201">Si vous marquez une méthode avec le [Async](../modifiers/async.md) modificateur, vous pouvez utiliser la [Await](../operators/await-operator.md) opérateur dans la méthode.</span><span class="sxs-lookup"><span data-stu-id="7e364-201">If you mark a method with the [Async](../modifiers/async.md) modifier, you can use the [Await](../operators/await-operator.md) operator in the method.</span></span> <span data-ttu-id="7e364-202">Une instruction avec le `Await` opérateur suspend l’exécution de la méthode jusqu'à ce que la tâche attendue se termine.</span><span class="sxs-lookup"><span data-stu-id="7e364-202">A statement with the `Await` operator suspends execution of the method until the awaited task completes.</span></span> <span data-ttu-id="7e364-203">La tâche représente un travail en cours.</span><span class="sxs-lookup"><span data-stu-id="7e364-203">The task represents ongoing work.</span></span> <span data-ttu-id="7e364-204">Lorsque la tâche qui est associée la `Await` opérateur terminée, l’exécution reprend dans la même méthode.</span><span class="sxs-lookup"><span data-stu-id="7e364-204">When the task that's associated with the `Await` operator finishes, execution resumes in the same method.</span></span> <span data-ttu-id="7e364-205">Pour plus d’informations, consultez [flux de contrôle dans les programmes Async](../../../visual-basic/programming-guide/concepts/async/control-flow-in-async-programs.md).</span><span class="sxs-lookup"><span data-stu-id="7e364-205">For more information, see [Control Flow in Async Programs](../../../visual-basic/programming-guide/concepts/async/control-flow-in-async-programs.md).</span></span>

<span data-ttu-id="7e364-206">Une tâche retournée par une méthode Async peut se terminer par un état d’erreur, indiquant qu’il est terminé en raison d’une exception non gérée.</span><span class="sxs-lookup"><span data-stu-id="7e364-206">A task returned by an Async method may end in a faulted state, indicating that it completed due to an unhandled exception.</span></span> <span data-ttu-id="7e364-207">Une tâche peut également se terminer dans un état annulé, ce qui entraîne un `OperationCanceledException` levée en dehors de l’expression await.</span><span class="sxs-lookup"><span data-stu-id="7e364-207">A task may also end in a canceled state, which results in an `OperationCanceledException` being thrown out of the await expression.</span></span> <span data-ttu-id="7e364-208">Pour intercepter un type d’exception, placez le `Await` expression qui est associé à la tâche dans un `Try` bloquer et intercepter l’exception dans le `Catch` bloc.</span><span class="sxs-lookup"><span data-stu-id="7e364-208">To catch either type of exception, place the `Await` expression that's associated with the task in a `Try` block, and catch the exception in the `Catch` block.</span></span> <span data-ttu-id="7e364-209">Un exemple est fourni plus loin dans cette rubrique.</span><span class="sxs-lookup"><span data-stu-id="7e364-209">An example is provided later in this topic.</span></span>

<span data-ttu-id="7e364-210">Une tâche peut être dans un état d’erreur, car plusieurs exceptions ont été responsables de sa défaillance.</span><span class="sxs-lookup"><span data-stu-id="7e364-210">A task can be in a faulted state because multiple exceptions were responsible for its faulting.</span></span> <span data-ttu-id="7e364-211">Par exemple, la tâche peut être le résultat d'un appel à <xref:System.Threading.Tasks.Task.WhenAll%2A?displayProperty=nameWithType>.</span><span class="sxs-lookup"><span data-stu-id="7e364-211">For example, the task might be the result of a call to <xref:System.Threading.Tasks.Task.WhenAll%2A?displayProperty=nameWithType>.</span></span> <span data-ttu-id="7e364-212">Lorsque vous attendez une telle tâche, l’exception interceptée est uniquement une des exceptions, et vous ne pouvez pas prédire quelle exception est interceptée.</span><span class="sxs-lookup"><span data-stu-id="7e364-212">When you await such a task, the caught exception is only one of the exceptions, and you can't predict which exception will be caught.</span></span> <span data-ttu-id="7e364-213">Un exemple est fourni plus loin dans cette rubrique.</span><span class="sxs-lookup"><span data-stu-id="7e364-213">An example is provided later in this topic.</span></span>

<span data-ttu-id="7e364-214">Un `Await` expression ne peut pas être à l’intérieur d’un `Catch` bloc ou `Finally` bloc.</span><span class="sxs-lookup"><span data-stu-id="7e364-214">An `Await` expression can't be inside a `Catch` block or `Finally` block.</span></span>

## <a name="iterators"></a><span data-ttu-id="7e364-215">Iterators</span><span class="sxs-lookup"><span data-stu-id="7e364-215">Iterators</span></span>

<span data-ttu-id="7e364-216">Une fonction d’itérateur ou `Get` accesseur effectue une itération personnalisée sur une collection.</span><span class="sxs-lookup"><span data-stu-id="7e364-216">An iterator function or `Get` accessor performs a custom iteration over a collection.</span></span> <span data-ttu-id="7e364-217">Un itérateur utilise une [Yield](yield-statement.md) instruction pour retourner chaque élément de la collection un à la fois.</span><span class="sxs-lookup"><span data-stu-id="7e364-217">An iterator uses a [Yield](yield-statement.md) statement to return each element of the collection one at a time.</span></span> <span data-ttu-id="7e364-218">Vous appelez une fonction d’itérateur en utilisant un [For Each... L’instruction suivante](for-each-next-statement.md).</span><span class="sxs-lookup"><span data-stu-id="7e364-218">You call an iterator function by using a [For Each...Next Statement](for-each-next-statement.md).</span></span>

<span data-ttu-id="7e364-219">Un `Yield` instruction peut être à l’intérieur d’un `Try` bloc.</span><span class="sxs-lookup"><span data-stu-id="7e364-219">A `Yield` statement can be inside a `Try` block.</span></span> <span data-ttu-id="7e364-220">Un `Try` bloc qui contient un `Yield` instruction peut avoir `Catch` bloque et peut avoir un `Finally` bloc.</span><span class="sxs-lookup"><span data-stu-id="7e364-220">A `Try` block that contains a `Yield` statement can have `Catch` blocks, and can have a `Finally` block.</span></span> <span data-ttu-id="7e364-221">Consultez la section « Essayez de blocs dans Visual Basic » de [itérateurs](../../programming-guide/concepts/iterators.md) pour obtenir un exemple.</span><span class="sxs-lookup"><span data-stu-id="7e364-221">See the "Try Blocks in Visual Basic" section of [Iterators](../../programming-guide/concepts/iterators.md) for an example.</span></span>

<span data-ttu-id="7e364-222">Un `Yield` instruction ne peut pas être à l’intérieur d’un `Catch` bloc ou une `Finally` bloc.</span><span class="sxs-lookup"><span data-stu-id="7e364-222">A `Yield` statement cannot be inside a `Catch` block or a `Finally` block.</span></span>

<span data-ttu-id="7e364-223">Si le `For Each` corps (en dehors de la fonction d’itérateur) lève une exception, un `Catch` bloc dans la fonction d’itérateur n’est pas exécuté, mais un `Finally` bloc dans la fonction d’itérateur est exécuté.</span><span class="sxs-lookup"><span data-stu-id="7e364-223">If the `For Each` body (outside of the iterator function) throws an exception, a `Catch` block in the iterator function is not executed, but a `Finally` block in the iterator function is executed.</span></span> <span data-ttu-id="7e364-224">Un `Catch` bloc à l’intérieur d’une fonction d’itérateur intercepte uniquement les exceptions qui se produisent à l’intérieur de la fonction d’itérateur.</span><span class="sxs-lookup"><span data-stu-id="7e364-224">A `Catch` block inside an iterator function catches only exceptions that occur inside the iterator function.</span></span>

## <a name="partial-trust-situations"></a><span data-ttu-id="7e364-225">Situations de confiance partielle</span><span class="sxs-lookup"><span data-stu-id="7e364-225">Partial-trust situations</span></span>

<span data-ttu-id="7e364-226">Dans les situations de confiance partielle, tel qu’une application hébergée sur un partage réseau, `Try...Catch...Finally` n’intercepte pas les exceptions de sécurité qui se produisent avant l’appel de la méthode qui contient l’appel.</span><span class="sxs-lookup"><span data-stu-id="7e364-226">In partial-trust situations, such as an application hosted on a network share, `Try...Catch...Finally` does not catch security exceptions that occur before the method that contains the call is invoked.</span></span> <span data-ttu-id="7e364-227">L’exemple suivant, lorsque vous placez sur un partage de serveur et que vous exécutez à partir de là, génère l’erreur « System.Security.SecurityException : Échoué de la demande. »</span><span class="sxs-lookup"><span data-stu-id="7e364-227">The following example, when you put it on a server share and run from there, produces the error "System.Security.SecurityException: Request Failed."</span></span> <span data-ttu-id="7e364-228">Pour plus d’informations sur les exceptions de sécurité, consultez la <xref:System.Security.SecurityException> classe.</span><span class="sxs-lookup"><span data-stu-id="7e364-228">For more information about security exceptions, see the <xref:System.Security.SecurityException> class.</span></span>

[!code-vb[VbVbalrStatements#85](~/samples/snippets/visualbasic/VS_Snippets_VBCSharp/VbVbalrStatements/VB/Class1.vb#85)]

<span data-ttu-id="7e364-229">Dans une telle situation de confiance partielle, vous devez placer le `Process.Start` instruction dans une fonction `Sub`.</span><span class="sxs-lookup"><span data-stu-id="7e364-229">In such a partial-trust situation, you have to put the `Process.Start` statement in a separate `Sub`.</span></span> <span data-ttu-id="7e364-230">L’appel initial à la `Sub` échoue.</span><span class="sxs-lookup"><span data-stu-id="7e364-230">The initial call to the `Sub` will fail.</span></span> <span data-ttu-id="7e364-231">Cela permet de `Try...Catch` de l’intercepter avant le `Sub` contenant `Process.Start` est démarré et généré l’exception de sécurité.</span><span class="sxs-lookup"><span data-stu-id="7e364-231">This enables `Try...Catch` to catch it before the `Sub` that contains `Process.Start` is started and the security exception produced.</span></span>

## <a name="examples"></a><span data-ttu-id="7e364-232">Exemples</span><span class="sxs-lookup"><span data-stu-id="7e364-232">Examples</span></span>

### <a name="the-structure-of-trycatchfinally"></a><span data-ttu-id="7e364-233">La structure de Try... Catch... Enfin</span><span class="sxs-lookup"><span data-stu-id="7e364-233">The structure of Try...Catch...Finally</span></span>

<span data-ttu-id="7e364-234">L’exemple suivant illustre la structure de la `Try...Catch...Finally` instruction.</span><span class="sxs-lookup"><span data-stu-id="7e364-234">The following example illustrates the structure of the `Try...Catch...Finally` statement.</span></span>

[!code-vb[VbVbalrStatements#86](~/samples/snippets/visualbasic/VS_Snippets_VBCSharp/VbVbalrStatements/VB/Class1.vb#86)]  

### <a name="exception-in-a-method-called-from-a-try-block"></a><span data-ttu-id="7e364-235">Exception dans une méthode appelée à partir d’un bloc Try</span><span class="sxs-lookup"><span data-stu-id="7e364-235">Exception in a method called from a Try block</span></span>

<span data-ttu-id="7e364-236">Dans l’exemple suivant, le `CreateException` méthode lève un `NullReferenceException`.</span><span class="sxs-lookup"><span data-stu-id="7e364-236">In the following example, the `CreateException` method throws a `NullReferenceException`.</span></span> <span data-ttu-id="7e364-237">Le code qui génère l’exception n’est pas dans un `Try` bloc.</span><span class="sxs-lookup"><span data-stu-id="7e364-237">The code that generates the exception is not in a `Try` block.</span></span> <span data-ttu-id="7e364-238">Par conséquent, le `CreateException` méthode ne gère pas l’exception.</span><span class="sxs-lookup"><span data-stu-id="7e364-238">Therefore, the `CreateException` method does not handle the exception.</span></span> <span data-ttu-id="7e364-239">Le `RunSample` méthode gère l’exception, car l’appel à la `CreateException` méthode se trouve dans un `Try` bloc.</span><span class="sxs-lookup"><span data-stu-id="7e364-239">The `RunSample` method does handle the exception because the call to the `CreateException` method is in a `Try` block.</span></span>

<span data-ttu-id="7e364-240">L’exemple inclut `Catch` instructions pour plusieurs types d’exceptions, classées de la plus spécifique au plus général.</span><span class="sxs-lookup"><span data-stu-id="7e364-240">The example includes `Catch` statements for several types of exceptions, ordered from the most specific to the most general.</span></span>

[!code-vb[VbVbalrStatements#91](~/samples/snippets/visualbasic/VS_Snippets_VBCSharp/VbVbalrStatements/VB/Class1.vb#91)]

### <a name="the-catch-when-statement"></a><span data-ttu-id="7e364-241">L’instruction Catch lorsque</span><span class="sxs-lookup"><span data-stu-id="7e364-241">The Catch When statement</span></span>

<span data-ttu-id="7e364-242">L’exemple suivant montre comment utiliser un `Catch When` instruction pour filtrer sur une expression conditionnelle.</span><span class="sxs-lookup"><span data-stu-id="7e364-242">The following example shows how to use a `Catch When` statement to filter on a conditional expression.</span></span> <span data-ttu-id="7e364-243">Si l’expression conditionnelle a la valeur `True`, le code dans le `Catch` bloquer s’exécute.</span><span class="sxs-lookup"><span data-stu-id="7e364-243">If the conditional expression evaluates to `True`, the code in the `Catch` block runs.</span></span>

[!code-vb[VbVbalrStatements#92](~/samples/snippets/visualbasic/VS_Snippets_VBCSharp/VbVbalrStatements/VB/Class1.vb#92)]

### <a name="nested-try-statements"></a><span data-ttu-id="7e364-244">Instructions Try imbriquées</span><span class="sxs-lookup"><span data-stu-id="7e364-244">Nested Try statements</span></span>

<span data-ttu-id="7e364-245">L’exemple suivant comprend un `Try…Catch` instruction qui est contenue dans un `Try` bloc.</span><span class="sxs-lookup"><span data-stu-id="7e364-245">The following example has a `Try…Catch` statement that is contained in a `Try` block.</span></span> <span data-ttu-id="7e364-246">Interne `Catch` bloc lève une exception qui a son `InnerException` propriété définie à l’exception d’origine.</span><span class="sxs-lookup"><span data-stu-id="7e364-246">The inner `Catch` block throws an exception that has its `InnerException` property set to the original exception.</span></span> <span data-ttu-id="7e364-247">Externe `Catch` bloc signale sa propre exception et l’exception interne.</span><span class="sxs-lookup"><span data-stu-id="7e364-247">The outer `Catch` block reports its own exception and the inner exception.</span></span>

[!code-vb[VbVbalrStatements#93](~/samples/snippets/visualbasic/VS_Snippets_VBCSharp/VbVbalrStatements/VB/Class1.vb#93)]

### <a name="exception-handling-for-async-methods"></a><span data-ttu-id="7e364-248">Gestion des exceptions pour les méthodes async</span><span class="sxs-lookup"><span data-stu-id="7e364-248">Exception handling for async methods</span></span>

<span data-ttu-id="7e364-249">L'exemple suivant illustre la gestion des exceptions pour les méthodes async.</span><span class="sxs-lookup"><span data-stu-id="7e364-249">The following example illustrates exception handling for async methods.</span></span> <span data-ttu-id="7e364-250">Pour intercepter une exception qui s’applique à une tâche asynchrone, le `Await` expression est dans un `Try` bloc de l’appelant et l’exception est interceptée dans le `Catch` bloc.</span><span class="sxs-lookup"><span data-stu-id="7e364-250">To catch an exception that applies to an async task, the `Await` expression is in a `Try` block of the caller, and the exception is caught in the `Catch` block.</span></span>

<span data-ttu-id="7e364-251">Supprimez les marques de commentaire de la ligne `Throw New Exception` dans l'exemple pour illustrer la gestion des exceptions.</span><span class="sxs-lookup"><span data-stu-id="7e364-251">Uncomment the `Throw New Exception` line in the example to demonstrate exception handling.</span></span> <span data-ttu-id="7e364-252">L’exception est interceptée dans le `Catch` bloquer, de la tâche `IsFaulted` propriété est définie sur `True`et de la tâche `Exception.InnerException` propriété est définie à l’exception.</span><span class="sxs-lookup"><span data-stu-id="7e364-252">The exception is caught in the `Catch` block, the task's `IsFaulted` property is set to `True`, and the task's `Exception.InnerException` property is set to the exception.</span></span>

<span data-ttu-id="7e364-253">Supprimez les marques de commentaire de la ligne `Throw New OperationCancelledException` pour montrer ce qui se passe quand vous annulez un processus asynchrone.</span><span class="sxs-lookup"><span data-stu-id="7e364-253">Uncomment the `Throw New OperationCancelledException` line to demonstrate what happens when you cancel an asynchronous process.</span></span> <span data-ttu-id="7e364-254">L’exception est interceptée dans le `Catch` bloc et de la tâche `IsCanceled` propriété est définie sur `True`.</span><span class="sxs-lookup"><span data-stu-id="7e364-254">The exception is caught in the `Catch` block, and the task's `IsCanceled` property is set to `True`.</span></span> <span data-ttu-id="7e364-255">Toutefois, dans certaines conditions qui s’appliquent à cet exemple, `IsFaulted` a la valeur `True` et `IsCanceled` est défini sur `False`.</span><span class="sxs-lookup"><span data-stu-id="7e364-255">However, under some conditions that don't apply to this example, `IsFaulted` is set to `True` and `IsCanceled` is set to `False`.</span></span>

[!code-vb[csAsyncExceptions#1](~/samples/snippets/visualbasic/VS_Snippets_VBCSharp/csasyncexceptions/vb/class1.vb#1)]

### <a name="handling-multiple-exceptions-in-async-methods"></a><span data-ttu-id="7e364-256">Gestion des exceptions multiples dans les méthodes async</span><span class="sxs-lookup"><span data-stu-id="7e364-256">Handling multiple exceptions in async methods</span></span>

<span data-ttu-id="7e364-257">L’exemple suivant illustre la gestion des exceptions quand plusieurs tâches peuvent entraîner plusieurs exceptions.</span><span class="sxs-lookup"><span data-stu-id="7e364-257">The following example illustrates exception handling where multiple tasks can result in multiple exceptions.</span></span> <span data-ttu-id="7e364-258">Le `Try` bloc a le `Await` expression pour la tâche qui <xref:System.Threading.Tasks.Task.WhenAll%2A?displayProperty=nameWithType> retourné.</span><span class="sxs-lookup"><span data-stu-id="7e364-258">The `Try` block has the `Await` expression for the task that <xref:System.Threading.Tasks.Task.WhenAll%2A?displayProperty=nameWithType> returned.</span></span> <span data-ttu-id="7e364-259">La tâche est terminée lorsque les trois tâches auquel <xref:System.Threading.Tasks.Task.WhenAll%2A?displayProperty=nameWithType> est appliqué sont terminées.</span><span class="sxs-lookup"><span data-stu-id="7e364-259">The task is complete when the three tasks to which <xref:System.Threading.Tasks.Task.WhenAll%2A?displayProperty=nameWithType> is applied are complete.</span></span>

<span data-ttu-id="7e364-260">Chacune de ces trois tâches provoque une exception.</span><span class="sxs-lookup"><span data-stu-id="7e364-260">Each of the three tasks causes an exception.</span></span> <span data-ttu-id="7e364-261">Le `Catch` bloc effectue une itération dans les exceptions qui se trouvent dans le `Exception.InnerExceptions` propriété de la tâche qui `Task.WhenAll` retourné.</span><span class="sxs-lookup"><span data-stu-id="7e364-261">The `Catch` block iterates through the exceptions, which are found in the `Exception.InnerExceptions` property of the task that `Task.WhenAll` returned.</span></span>

[!code-vb[csAsyncExceptions#3](~/samples/snippets/visualbasic/VS_Snippets_VBCSharp/csasyncexceptions/vb/class1.vb#3)]

## <a name="see-also"></a><span data-ttu-id="7e364-262">Voir aussi</span><span class="sxs-lookup"><span data-stu-id="7e364-262">See also</span></span>

- <xref:Microsoft.VisualBasic.Information.Err%2A>
- <xref:System.Exception>
- [<span data-ttu-id="7e364-263">Exit (instruction)</span><span class="sxs-lookup"><span data-stu-id="7e364-263">Exit Statement</span></span>](exit-statement.md)
- [<span data-ttu-id="7e364-264">On Error (instruction)</span><span class="sxs-lookup"><span data-stu-id="7e364-264">On Error Statement</span></span>](on-error-statement.md)
- [<span data-ttu-id="7e364-265">Bonnes pratiques pour l’utilisation des extraits de code</span><span class="sxs-lookup"><span data-stu-id="7e364-265">Best Practices for Using Code Snippets</span></span>](/visualstudio/ide/best-practices-for-using-code-snippets)
- [<span data-ttu-id="7e364-266">Gestion des exceptions</span><span class="sxs-lookup"><span data-stu-id="7e364-266">Exception Handling</span></span>](../../../standard/parallel-programming/exception-handling-task-parallel-library.md)
- [<span data-ttu-id="7e364-267">Throw (instruction)</span><span class="sxs-lookup"><span data-stu-id="7e364-267">Throw Statement</span></span>](throw-statement.md)
