---
title: "'Catch' ne peut pas apparaître après 'Finally' dans une instruction 'Try'"
ms.date: 07/20/2015
f1_keywords:
- vbc30379
- bc30379
helpviewer_keywords:
- BC30379
ms.assetid: 33d1278b-cf10-4c66-aaf8-08a4372f370b
ms.openlocfilehash: ab300d332dd82870901aec9bd57d8d5d8081a533
ms.sourcegitcommit: f8c270376ed905f6a8896ce0fe25b4f4b38ff498
ms.translationtype: MT
ms.contentlocale: fr-FR
ms.lasthandoff: 06/04/2020
ms.locfileid: "84403769"
---
# <a name="catch-cannot-appear-after-finally-within-a-try-statement"></a>'Catch' ne peut pas apparaître après 'Finally' dans une instruction 'Try'
Une instruction `Catch` apparaît dans le code après `Finally` qui termine un bloc d’instruction `Try` . `Catch` doit apparaître dans un bloc d’instruction `Try...Catch...Finally` .  
  
 **ID d’erreur :** BC30379  
  
## <a name="to-correct-this-error"></a>Pour corriger cette erreur  
  
1. Déplacez l’instruction `Catch` vers un emplacement plus approprié dans le code.  
  
## <a name="see-also"></a>Voir aussi

- [Try...Catch...Finally (instruction)](../language-reference/statements/try-catch-finally-statement.md)
