---
title: L’instruction 'Throw' ne peut pas omettre l’opérande en dehors d’une instruction 'Catch' ou dans une instruction 'Finally'
ms.date: 07/20/2015
f1_keywords:
- vbc30666
- bc30666
helpviewer_keywords:
- BC30666
ms.assetid: a208a6ea-0e36-4bf1-8984-4de1a0e38a2a
ms.openlocfilehash: c4ab115b01e78c245cbd9f564b50573d6e30c5e7
ms.sourcegitcommit: f8c270376ed905f6a8896ce0fe25b4f4b38ff498
ms.translationtype: MT
ms.contentlocale: fr-FR
ms.lasthandoff: 06/04/2020
ms.locfileid: "84414931"
---
# <a name="throw-statement-cannot-omit-operand-outside-a-catch-statement-or-inside-a-finally-statement"></a>L’instruction 'Throw' ne peut pas omettre l’opérande en dehors d’une instruction 'Catch' ou dans une instruction 'Finally'
Les instructions`Throw` situées en dehors de l’instruction `Catch` doivent fournir le nom d’un objet exception.  
  
 **ID d’erreur :** BC30666  
  
## <a name="to-correct-this-error"></a>Pour corriger cette erreur  
  
1. Spécifiez le nom d’un objet d’exception dérivé de `System.Exception`.  
  
2. Restructurez votre code pour que l’instruction `Throw` se trouve dans un bloc `Catch` .  
  
## <a name="see-also"></a>Voir aussi

- [Throw (instruction)](../language-reference/statements/throw-statement.md)
- [Try...Catch...Finally (instruction)](../language-reference/statements/try-catch-finally-statement.md)
- <xref:System.Exception?displayProperty=nameWithType>
- [Gestion et levée d’exceptions dans .NET](../../standard/exceptions/index.md)
