---
title: "'Catch' ne peut pas apparaître après 'Finally' dans une instruction 'Try'"
ms.date: 07/20/2015
f1_keywords:
- vbc30379
- bc30379
helpviewer_keywords:
- BC30379
ms.assetid: 33d1278b-cf10-4c66-aaf8-08a4372f370b
ms.openlocfilehash: 327bec408905c927c5232297f87b8f54ec941beb
ms.sourcegitcommit: bf5c5850654187705bc94cc40ebfb62fe346ab02
ms.translationtype: MT
ms.contentlocale: fr-FR
ms.lasthandoff: 09/23/2020
ms.locfileid: "91074561"
---
# <a name="catch-cannot-appear-after-finally-within-a-try-statement"></a>'Catch' ne peut pas apparaître après 'Finally' dans une instruction 'Try'

Une instruction `Catch` apparaît dans le code après `Finally` qui termine un bloc d’instruction `Try` . `Catch` doit apparaître dans un bloc d’instruction `Try...Catch...Finally` .  
  
 **ID d’erreur :** BC30379  
  
## <a name="to-correct-this-error"></a>Pour corriger cette erreur  
  
1. Déplacez l’instruction `Catch` vers un emplacement plus approprié dans le code.  
  
## <a name="see-also"></a>Voir aussi

- [Try...Catch...Finally (instruction)](../language-reference/statements/try-catch-finally-statement.md)
